Workbook

Sheet README
A1: Caterpillar — Eight-Quarter Operating Dataset, Q3 2024 to Q2 2026
A2: Supporting workbook for the case study "Caterpillar demand quality". Every figure traces to a document listed on the Source Index tab.
A4: Financial figures are sourced to Caterpillar and SEC filings wherever available. Management commentary not reproduced in a filing is
A5: identified as earnings-call commentary and supported by transcript sources. No third-party estimates or analyst summaries are used as
A6: financial inputs. All 17 source links were opened and confirmed live on 5 October 2026.
A8: START HERE
A9: 1. Analysis — the worked question: did growth come from end-user demand or dealer restocking? Everything else feeds this tab.
A10: 2. Construction Industries, Dealer Inventory, Retail Statistics — the three tabs the finding actually rests on.
A11: 3. Comparability Log — 16 logged issues. Read this before reusing any series. It is the reason several obvious charts are wrong.
A12: 4. Source Index — every document, with a direct link.
A14: Tab colours follow that path: blue = start, green = destination, grey = source data, orange = logs and sourcing.
A16: CLASSIFICATION
... A39: The reported-vs-retail gap is a directional indicator of dealer stocking, not an exact dollar measure of inventory.

Sheet Analysis
A1: Analysis — Construction Industries, formula-linked to the source tabs
A2: Cells below are formulas pointing at Consolidated / Construction Industries / Retail Statistics / Dealer Inventory / Cash Flow, with three typed exceptions: row 20 (prior-year margins, from the releases), rows 41-42 (disclosed builds, from the Dealer Inventory tab quotes) and the 0.034 in I56 (the 340 bps disclosed on the Q2 2026 call).
A3: CI is used because it is the only segment unaffected by the restatement (see Comparability Log item 3).
A5: Metric | B5: Q3 2024 | C5: Q4 2024 | D5: Q1 2025 | E5: Q2 2025 | F5: Q3 2025 | G5: Q4 2025 | H5: Q1 2026 | I5: Q2 2026 | J5: Class
A6: CI reported sales growth % | B6: ='Construction Industries'!B5/'Construction Industries'!B6-1 -> -0.09344192 | C6: ='Construction Industries'!C5/'Construction Industries'!C6-1 -> -0.079153244 | D6: ='Construction Industries'!D5/'Construction Industries'!D6-1 -> -0.19302615 | E6: ='Construction Industries'!E5/'Construction Industries'!E6-1 -> -0.073769265 | F6: ='Construction Industries'!F5/'Construction Industries'!F6-1 -> 0.065405831 | G6: ='Construction Industries'!G5/'Construction Industries'!G6-1 -> 0.15375646 | H6: ='Construction Industries'!H5/'Construction Industries'!H6-1 -> 0.38136574 | I6: ='Construction Industries'!I5/'Construction Industries'!I6-1 -> 0.34830372 | J6: CALC
A7: CI retail sales growth % (World) | B7: ='Retail Statistics'!B11 -> -0.07 | C7: ='Retail Statistics'!C11 -> -0.03 | D7: ='Retail Statistics'!D11 -> 0.03 | E7: ='Retail Statistics'!E11 -> 0.02 | F7: ='Retail Statistics'!F11 -> 0.07 | G7: ='Retail Statistics'!G11 -> 0.11 | H7: ='Retail Statistics'!H11 -> 0.07 | I7: ='Retail Statistics'!I11 -> 0.22 | J7: SOURCED link
A8: GAP: reported less retail (pts) | B8: =B6-B7 -> -0.02344192 | C8: =C6-C7 -> -0.049153244 | D8: =D6-D7 -> -0.22302615 | E8: =E6-E7 -> -0.093769265 | F8: =F6-F7 -> -0.0045941686 | G8: =G6-G7 -> 0.043756455 | H8: =H6-H7 -> 0.31136574 | I8: =I6-I7 -> 0.12830372 | J8: CALC
A10: CI price realization % of prior-yr sales | B10: ='Construction Industries'!B9/'Construction Industries'!B6 -> -0.021003 | C10: ='Construction Industries'!C9/'Construction Industries'!C6 -> -0.046019328 | D10: ='Construction Industries'!D9/'Construction Industries'!D6 -> -0.055261519 | E10: ='Construction Industries'!E9/'Construction Industries'!E6 -> -0.06868173 | F10: ='Construction Industries'!F9/'Construction Industries'!F6 -> -0.041292356 | G10: ='Construction Industries'!G9/'Construction Industries'!G6 -> -0.0099950025 | H10: ='Construction Industries'!H9/'Construction Industries'!H6 -> 0.06867284 | I10: ='Construction Industries'!I9/'Construction Industries'!I6 -> 0.049919225 | J10: CALC
A11: CI volume % of prior-yr sales | B11: ='Construction Industries'!B8/'Construction Industries'!B6 -> -0.06543792 | C11: ='Construction Industries'!C8/'Construction Industries'!C6 -> -0.034821292 | D11: ='Construction Industries'!D8/'Construction Industries'!D6 -> -0.12764633 | E11: ='Construction Industries'!E8/'Construction Industries'!E6 -> -0.012419572 | F11: ='Construction Industries'!F8/'Construction Industries'!F6 -> 0.089519307 | G11: ='Construction Industries'!G8/'Construction Industries'!G6 -> 0.15042479 | H11: ='Construction Industries'!H8/'Construction Industries'!H6 -> 0.2814429 | I11: ='Construction Industries'!I8/'Construction Industries'!I6 -> 0.28352181 | J11: CALC
A12: CI price-adjusted sales growth % | B12: =('Construction Industries'!B7-'Construction Industries'!B9)/'Construction Industries'!B6 -> -0.07243892 | C12: =('Construction Industries'!C7-'Construction Industries'!C9)/'Construction Industries'!C6 -> -0.033133916 | D12: =('Construction Industries'!D7-'Construction Industries'!D9)/'Construction Industries'!D6 -> -0.13776463 | E12: =('Construction Industries'!E7-'Construction Industries'!E9)/'Construction Industries'!E6 -> -0.0050875355 | F12: =('Construction Industries'!F7-'Construction Industries'!F9)/'Construction Industries'!F6 -> 0.10669819 | G12: =('Construction Industries'!G7-'Construction Industries'!G9)/'Construction Industries'!G6 -> 0.16375146 | H12: =('Construction Industries'!H7-'Construction Industries'!H9)/'Construction Industries'!H6 -> 0.3126929 | I12: =('Construction Industries'!I7-'Construction Industries'!I9)/'Construction Industries'!I6 -> 0.29838449 | J12: CALC
A13: ADJUSTED GAP: price-adj less retail (pts; retail is disclosed in whole %, so about +/-0.5 pt) | B13: =B12-B7 -> -0.0024389198 | C13: =C12-C7 -> -0.0031339162 | D13: =D12-D7 -> -0.16776463 | E13: =E12-E7 -> -0.025087536 | F13: =F12-F7 -> 0.036698188 | G13: =G12-G7 -> 0.053751458 | H13: =H12-H7 -> 0.2426929 | I13: =I12-I7 -> 0.078384491 | J13: CALC
A15: CI dealer inventory change $mm | B15: =IF('Dealer Inventory'!G4="","",'Dealer Inventory'!G4) | C15: =IF('Dealer Inventory'!G5="","",'Dealer Inventory'!G5) | D15: =IF('Dealer Inventory'!G6="","",'Dealer Inventory'!G6) | E15: =IF('Dealer Inventory'!G7="","",'Dealer Inventory'!G7) | F15: =IF('Dealer Inventory'!G8="","",'Dealer Inventory'!G8) | G15: =IF('Dealer Inventory'!G9="","",'Dealer Inventory'!G9) | H15: =IF('Dealer Inventory'!G10="","",'Dealer Inventory'!G10) -> 1500 | I15: =IF('Dealer Inventory'!G11="","",'Dealer Inventory'!G11) -> 400 | J15: SOURCED link / blank
A16: Company-wide dealer inventory change $mm | B16: =IF('Dealer Inventory'!B4="","",'Dealer Inventory'!B4) | C16: =IF('Dealer Inventory'!B5="","",'Dealer Inventory'!B5) -> -1300 | D16: =IF('Dealer Inventory'!B6="","",'Dealer Inventory'!B6) -> 100 | E16: =IF('Dealer Inventory'!B7="","",'Dealer Inventory'!B7) | F16: =IF('Dealer Inventory'!B8="","",'Dealer Inventory'!B8) | G16: =IF('Dealer Inventory'!B9="","",'Dealer Inventory'!B9) -> 0 | H16: =IF('Dealer Inventory'!B10="","",'Dealer Inventory'!B10) -> 2000 | I16: =IF('Dealer Inventory'!B11="","",'Dealer Inventory'!B11)
A17: Dealer inventory classification | B17: Undisclosed | C17: Draw | D17: Build (slight) | E17: Draw | F17: Build | G17: Neutral | H17: Build | I17: Build | J17: From CAT wording
A19: CI segment profit margin | B19: ='Construction Industries'!B15 -> 0.234 | C19: ='Construction Industries'!C15 -> 0.196 | D19: ='Construction Industries'!D15 -> 0.198 | E19: ='Construction Industries'!E15 -> 0.201 | F19: ='Construction Industries'!F15 -> 0.204 | G19: ='Construction Industries'!G15 -> 0.149 | H19: ='Construction Industries'!H15 -> 0.214 | I19: ='Construction Industries'!I15 -> 0.233 | J19: SOURCED link
A20: CI prior-year margin | B20: 0.264 | C20: 0.235 | D20: 0.275 | F20: 0.234 | G20: 0.196 | H20: 0.198 | I20: 0.201 | J20: SOURCED
A21: YoY margin change (bps) | B21: =(B19-B20)*10000 -> -300 | C21: =(C19-C20)*10000 -> -390 | D21: =(D19-D20)*10000 -> -770 | F21: =(F19-F20)*10000 -> -300 | G21: =(G19-G20)*10000 -> -470 | H21: =(H19-H20)*10000 -> 160 | I21: =(I19-I20)*10000 -> 320 | J21: CALC
A23: Standalone quarterly OCF $mm | B23: ='Cash Flow'!B6 -> 3600 | E23: ='Cash Flow'!B21 -> 3122 | F23: ='Cash Flow'!B22 -> 3737 | G23: ='Cash Flow'!B23 -> 3591 | H23: ='Cash Flow'!B11 -> 1870 | I23: ='Cash Flow'!B24 -> 4371 | J23: DERIVED link
A24: Standalone quarterly capex $mm | G24: ='Cash Flow'!C23 -> 898 | H24: ='Cash Flow'!C11 -> 728 | I24: ='Cash Flow'!C24 -> 587 | J24: DERIVED link
A25: OCF as % of consolidated sales | B25: =IFERROR(B23/Consolidated!B5,"") -> 0.22351919 | E25: =IFERROR(E23/Consolidated!E5,"") -> 0.18842417 | F25: =IFERROR(F23/Consolidated!F5,"") -> 0.21187209 | G25: =IFERROR(G23/Consolidated!G5,"") -> 0.1876862 | H25: =IFERROR(H23/Consolidated!H5,"") -> 0.1073787 | I25: =IFERROR(I23/Consolidated!I5,"") -> 0.21277321 | J25: CALC
A27: Volume driver mentioned first (order of mention only) | B27: Not captured | C27: Not captured | D27: Not captured | E27: Not captured | F27: Not captured | G27: Not captured | H27: Dealer inventory (listed first) | I27: End-user demand (listed first) | J27: CAT wording only
A29: Q1 2026: "Higher sales volume was mainly driven by the impact from changes in dealer inventories and higher sales of equipment to end users."
A30: Q2 2026: "Higher sales volume was mainly driven by higher sales of equipment to end users and by the impact from changes in dealer inventories."
A31: INTERPRETIVE: the order of mention inverts between these two quarters (both quotes are SOURCED). Reading that order as relative magnitude is an analytical inference: Caterpillar does not say it lists drivers by size. Treat it as consistent with the dealer-inventory dollars, not as a measure of either driver.
A32: "Not captured" means the volume-driver sentence for that quarter has not been read from its release — NOT that no driver existed. Completing these six requires reading each release.
A33: LIMITATION OF THE GAP METRIC — revised 2 Oct after reading the retail basis notes.
A34: CORRECTION to the earlier version of this note: mix does NOT contaminate the gap the way I first wrote. Caterpillar reports CI retail sales in "price neutral dollars and based on unit sales as reported by dealers" (Ex 99.2, 2Q 2026). Both sides of the gap are therefore price-neutral dollar measures of units, so a shift toward larger machines raises BOTH and largely cancels.
A35: What does NOT cancel: (1) reported CI sales include parts and services, which have no counterpart in a retail series that measures machines to end users; (2) the disclosed dealer-inventory dollars are current-price, while the gap is price-neutral; (3) currency translation may be treated differently on the two sides; (4) the retail percentage is applied to a reported-sales base, because Caterpillar publishes retail only as a percentage.
A36: Net effect: the gap is a directional and relative measure of dealer stocking, NOT a dollar measurement. Where a disclosed dealer-inventory dollar exists, show it alongside the gap — do not let the gap stand in for it.
A38: VALIDATION TEST — does the gap actually measure dealer stocking?
A39: CONCEPTUAL RELATION, NOT AN ACCOUNTING IDENTITY: shipments to dealers are roughly retail sales to end users plus the change in dealer inventory. Because the two disclosures differ in price basis, scope, parts and services, and possibly currency (rows 33-36), row 40 is a DIRECTIONAL dollar estimate of the year-over-year change in the build, build(t) less build(t-4). Rows 41-42 are what Caterpillar actually disclosed. Only the SIGN can be tested against them.
A40: Implied stocking swing $mm (DERIVED from gap; directional - retail rounding alone is about +/-$30M) | B40: =('Construction Industries'!B7-'Construction Industries'!B9)-('Retail Statistics'!B11*'Construction Industries'!B6) -> -17.07 | C40: =('Construction Industries'!C7-'Construction Industries'!C9)-('Retail Statistics'!C11*'Construction Industries'!C6) -> -20.43 | D40: =('Construction Industries'!D7-'Construction Industries'!D9)-('Retail Statistics'!D11*'Construction Industries'!D6) -> -1077.72 | E40: =('Construction Industries'!E7-'Construction Industries'!E9)-('Retail Statistics'!E11*'Construction Industries'!E6) -> -167.66 | F40: =('Construction Industries'!F7-'Construction Industries'!F9)-('Retail Statistics'!F11*'Construction Industries'!F6) -> 232.85 | G40: =('Construction Industries'!G7-'Construction Industries'!G9)-('Retail Statistics'!G11*'Construction Industries'!G6) -> 322.67 | H40: =('Construction Industries'!H7-'Construction Industries'!H9)-('Retail Statistics'!H11*'Construction Industries'!H6) -> 1258.12 | I40: =('Construction Industries'!I7-'Construction Industries'!I9)-('Retail Statistics'!I11*'Construction Industries'!I6) -> 485.2
A41: Disclosed build, this quarter $mm (SOURCED) | D41: 100 | H41: 1500 | I41: 400
A42: Disclosed build, prior-year quarter (SOURCED) | D42: 1400 | H42: slight decrease (unquantified) | I42: decrease (unquantified)
A43: Scope of the disclosed figures | D43: Company-wide | H43: CI | I43: CI
A45: Q1 2025: implied -1,078 (CI estimate) against a company-wide swing of -1,300 (+100 less +1,400, both disclosed; the swing is DERIVED). SIGN AGREES. Scope differs (CI estimate vs company-wide disclosure), so magnitude is not tested.
A46: Q2 2026: implied +485 against a disclosed CI build of +400. The prior-year (Q2 2025) CI build has no dollar figure, only the CI North America narrative "dealer inventory decreased during the second quarter of 2025". SIGN AGREES; magnitude untestable.
A47: Q3 2025: implied +233. No dollar disclosed, but the narrative is an increase in Q3 2025 against a decrease in Q3 2024. Sign agrees; magnitude untestable.
A48: Q1 2026: implied +1,258 against a disclosed CI build of +1,500; the prior-year quarter was a 'slight decrease' (unquantified), so the true swing exceeds +1,500 by an unknown amount. SIGN AGREES; magnitude untestable.
A49: REFUTED — this is NOT a retail recast. The only CI period appearing in BOTH filing vintages is Q2 2025, and it reads UP 2% in each. The same cross-vintage test DOES detect a change in the Power & Energy Total (9% to 10%), so the test is sensitive enough to catch a recast — CI simply did not move. The 2026 realignment note concerns Rail / Resource Industries and Industrial, not Construction Industries.
...

Sheet Consolidated
A1: Consolidated Sales & Revenues ($mm)
A2: Blue = sourced. Orange = BACK-SOLVED (see note below). Black = formula. The reconciliation row is the integrity check: components must equal the change. A column with a back-solved component closes by construction.
A4: Line | B4: Q3 2024 | C4: Q4 2024 | D4: Q1 2025 | E4: Q2 2025 | F4: Q3 2025 | G4: Q4 2025 | H4: Q1 2026 | I4: Q2 2026 | J4: Class
A5: Total sales & revenues | B5: 16106 | C5: 16215 | D5: 14249 | E5: 16569 | F5: 17638 | G5: 19133 | H5: 17415 | I5: 20543 | J5: SOURCED
A6: Prior-year sales & revenues | B6: 16810 | C6: 17070 | D6: 15799 | E6: 16689 | F6: 16106 | G6: 16215 | H6: 14249 | I6: 16569 | J6: SOURCED
A7: Change (calc) | B7: =B5-B6 -> -704 | C7: =C5-C6 -> -855 | D7: =D5-D6 -> -1550 | E7: =E5-E6 -> -120 | F7: =F5-F6 -> 1532 | G7: =G5-G6 -> 2918 | H7: =H5-H6 -> 3166 | I7: =I5-I6 -> 3974 | J7: CALC
A8: Sales volume | B8: -759 | C8: -859 | D8: -1110 | E8: 237 | F8: 1554 | G8: 2708 | H8: 2318 | I8: 3113 | J8: SOURCED (I8: BACK-SOLVED)
A9: Price realization | B9: 104 | C9: -54 | D9: -250 | E9: -414 | F9: -191 | G9: 38 | H9: 426 | I9: 595 | J9: SOURCED
A10: Currency | B10: -102 | C10: 8 | D10: -222 | E10: 11 | F10: 132 | G10: 124 | H10: 351 | I10: 199 | J10: SOURCED
A11: Inter-segment / other | B11: 53 | C11: 50 | D11: 32 | E11: 46 | F11: 37 | G11: 48 | H11: 71 | I11: 67 | J11: SOURCED
A12: Sum of components (calc) | B12: =SUM(B8:B11) -> -704 | C12: =SUM(C8:C11) -> -855 | D12: =SUM(D8:D11) -> -1550 | E12: =SUM(E8:E11) -> -120 | F12: =SUM(F8:F11) -> 1532 | G12: =SUM(G8:G11) -> 2918 | H12: =SUM(H8:H11) -> 3166 | I12: =SUM(I8:I11) -> 3974 | J12: CALC
A13: RECONCILIATION (must be 0) | B13: =B7-B12 -> 0 | C13: =C7-C12 -> 0 | D13: =D7-D12 -> 0 | E13: =E7-E12 -> 0 | F13: =F7-F12 -> 0 | G13: =G7-G12 -> 0 | H13: =H7-H12 -> 0 | I13: =I7-I12 -> 0 | J13: CALC
A15: Q2 2026 sales volume of 3,113 is BACK-SOLVED: the release rounds it to "$3.1 billion", so it is backed out as the residual of the disclosed total. The Q2 2026 reconciliation therefore holds only within the rounding of that disclosure; it is not an independent check. Shown in orange.
A16: Operating cash flow and capex are disclosed year-to-date, not per quarter — see the Cash Flow tab for what exists.

Sheet Construction Industries
A1: Construction Industries ($mm) — consistent across all release vintages
A2: No restatement detected. CI prior-year figures in the 2026 releases match the originally reported quarters.
A4: Line | B4: Q3 2024 | C4: Q4 2024 | D4: Q1 2025 | E4: Q2 2025 | F4: Q3 2025 | G4: Q4 2025 | H4: Q1 2026 | I4: Q2 2026 | J4: Class
A5: Segment sales | B5: 6345 | C5: 6003 | D5: 5184 | E5: 6190 | F5: 6760 | G5: 6926 | H5: 7161 | I5: 8346 | J5: SOURCED
A6: Prior-year segment sales | B6: 6999 | C6: 6519 | D6: 6424 | E6: 6683 | F6: 6345 | G6: 6003 | H6: 5184 | I6: 6190 | J6: SOURCED (E6: BACK-SOLVED)
A7: Change (calc) | B7: =B5-B6 -> -654 | C7: =C5-C6 -> -516 | D7: =D5-D6 -> -1240 | E7: =E5-E6 -> -493 | F7: =F5-F6 -> 415 | G7: =G5-G6 -> 923 | H7: =H5-H6 -> 1977 | I7: =I5-I6 -> 2156 | J7: CALC
A8: Volume | B8: -458 | C8: -227 | D8: -820 | E8: -83 | F8: 568 | G8: 903 | H8: 1459 | I8: 1755 | J8: SOURCED
A9: Price realization | B9: -147 | C9: -300 | D9: -355 | E9: -459 | F9: -262 | G9: -60 | H9: 356 | I9: 309 | J9: SOURCED
A10: Currency | B10: -64 | C10: -2 | D10: -98 | E10: 9 | F10: 69 | G10: 44 | H10: 143 | I10: 74 | J10: SOURCED
A11: Inter-segment | B11: 15 | C11: 13 | D11: 33 | E11: 40 | F11: 40 | G11: 36 | H11: 19 | I11: 18 | J11: SOURCED
A12: Sum of components (calc) | B12: =SUM(B8:B11) -> -654 | C12: =SUM(C8:C11) -> -516 | D12: =SUM(D8:D11) -> -1240 | E12: =SUM(E8:E11) -> -493 | F12: =SUM(F8:F11) -> 415 | G12: =SUM(G8:G11) -> 923 | H12: =SUM(H8:H11) -> 1977 | I12: =SUM(I8:I11) -> 2156 | J12: CALC
A13: RECONCILIATION (must be 0) | B13: =B7-B12 -> 0 | C13: =C7-C12 -> 0 | D13: =D7-D12 -> 0 | E13: =E7-E12 -> 0 | F13: =F7-F12 -> 0 | G13: =G7-G12 -> 0 | H13: =H7-H12 -> 0 | I13: =I7-I12 -> 0 | J13: CALC
A14: Segment profit | B14: 1486 | C14: 1174 | D14: 1024 | E14: 1244 | F14: 1377 | G14: 1030 | H14: 1535 | I14: 1947 | J14: SOURCED
A15: Segment profit margin | B15: 0.234 | C15: 0.196 | D15: 0.198 | E15: 0.201 | F15: 0.204 | G15: 0.149 | H15: 0.214 | I15: 0.233 | J15: SOURCED
A17: Q2 2024 prior-year sales of 6,683 is BACK-SOLVED: 6,190 less the sum of the four disclosed Q2 2025 change components. The Q2 2025 reconciliation therefore closes by construction; it is not an independent check. Shown in orange.
A19: SEGMENT PROFIT BRIDGE — as disclosed by Caterpillar (SOURCED)
A20: Only the three quarters below were collected in this pass. Blank = not collected, NOT zero. Caterpillar itemises only the drivers it considers primary.
A21: Profit impact of sales volume | G21: 322 | H21: 505
A22: Price realization | G22: -60 | H22: 356
A23: Manufacturing costs | G23: -420 | H23: -362 | I23: Not disclosed
A24: Sum of disclosed drivers | G24: =SUM(G21:G23) -> -158 | H24: =SUM(H21:H23) -> 499
A25: Actual profit change vs PRIOR-YEAR quarter | G25: =G14-C14 -> -144 | H25: =H14-D14 -> 511 | I25: =I14-E14 -> 703
A26: Residual / undisclosed drivers (Q2 2026: entire change undisclosed) | G26: =G25-G24 -> 14 | H26: =H25-H24 -> 12 | I26: =I25 -> 703
A28: Q4 2025 and Q1 2026: "Unfavorable manufacturing costs largely reflected the impact of higher tariff costs." (4Q25 and 1Q26 earnings releases, Construction Industries segment discussion.) Q2 2026 discloses no manufacturing-cost driver for CI — the release says only "The increase was primarily due to the profit impact of higher sales volume," so the tariff drag cannot be quantified for that quarter and must NOT be assumed to be zero.
A29: Q2 2026 CI tariff impact is NOT in the release bridge above. It was disclosed on the call as 340 bps of margin (CFO Kyle Epley), converted to dollars on the Analysis tab as DERIVED. It is kept out of this bridge so the bridge stays release-sourced only.

Sheet Resource Industries
A1: Resource Industries ($mm) — RESTATED, two vintages
A2: Do not chart as one series. The 2026 releases show Q1 2025 RI as 3,661 and Q2 2025 as 3,886; those quarters were originally reported as 2,884 and 3,087.
A4: Line | B4: Q3 2024 | C4: Q4 2024 | D4: Q1 2025 | E4: Q2 2025 | F4: Q3 2025 | G4: Q4 2025 | H4: Q1 2026 | I4: Q2 2026 | J4: Class
A5: Segment sales (as reported) | B5: 3028 | C5: 2962 | D5: 2884 | E5: 3087 | F5: 3110 | G5: 3353 | H5: 3797 | I5: 4648 | J5: SOURCED
A6: Prior-year (as shown in release) | B6: 3351 | C6: 3242 | D6: 3193 | E6: 3206 | F6: 3048 | G6: 2980 | H6: 3661 | I6: 3886 | J6: SOURCED (E6: BACK-SOLVED)
A7: Change (calc) | B7: =B5-B6 -> -323 | C7: =C5-C6 -> -280 | D7: =D5-D6 -> -309 | E7: =E5-E6 -> -119 | F7: =F5-F6 -> 62 | G7: =G5-G6 -> 373 | H7: =H5-H6 -> 136 | I7: =I5-I6 -> 762 | J7: CALC
A8: Volume | B8: -352 | C8: -316 | D8: -179 | E8: -13 | F8: 138 | G8: 459 | H8: 85 | I8: 639 | J8: SOURCED
A9: Price realization | B9: 38 | C9: 26 | D9: -50 | E9: -94 | F9: -61 | G9: -67 | H9: -39 | I9: 75 | J9: SOURCED
A10: Currency | B10: -11 | C10: 3 | D10: -46 | E10: -11 | F10: 4 | G10: 7 | H10: 78 | I10: 65 | J10: SOURCED
A11: Inter-segment | B11: 2 | C11: 7 | D11: -34 | E11: -1 | F11: -19 | G11: -26 | H11: 12 | I11: -17 | J11: SOURCED
A12: Sum of components (calc) | B12: =SUM(B8:B11) -> -323 | C12: =SUM(C8:C11) -> -280 | D12: =SUM(D8:D11) -> -309 | E12: =SUM(E8:E11) -> -119 | F12: =SUM(F8:F11) -> 62 | G12: =SUM(G8:G11) -> 373 | H12: =SUM(H8:H11) -> 136 | I12: =SUM(I8:I11) -> 762 | J12: CALC
A13: RECONCILIATION (must be 0) | B13: =B7-B12 -> 0 | C13: =C7-C12 -> 0 | D13: =D7-D12 -> 0 | E13: =E7-E12 -> 0 | F13: =F7-F12 -> 0 | G13: =G7-G12 -> 0 | H13: =H7-H12 -> 0 | I13: =I7-I12 -> 0 | J13: CALC
A14: Segment profit | B14: 619 | C14: 466 | D14: 599 | E14: 537 | F14: 499 | G14: 360 | H14: 378 | I14: 693 | J14: SOURCED
A15: Segment profit margin | B15: 0.204 | C15: 0.157 | D15: 0.208 | E15: 0.174 | F15: 0.16 | G15: 0.107 | H15: 0.1 | I15: 0.149 | J15: SOURCED
A17: Shaded columns are post-restatement and are not comparable with the unshaded ones. Q2 2025 prior-year was not captured; left blank rather than estimated.
A18: Q2 2024 prior-year of 3,206 is BACK-SOLVED: Q2 2025 sales less the four disclosed change components. The Q2 2025 reconciliation therefore closes by construction; it is not an independent check. Shown in orange.

Sheet Power and Energy
A1: Energy & Transportation / Power & Energy ($mm) — RENAMED AND RESTATED
A2: Reported as "Energy & Transportation" through Q3 2025 and "Power & Energy" from Q4 2025. The 2026 releases also restate prior-year downward by roughly $800M per quarter.
A4: Line | B4: Q3 2024 | C4: Q4 2024 | D4: Q1 2025 | E4: Q2 2025 | F4: Q3 2025 | G4: Q4 2025 | H4: Q1 2026 | I4: Q2 2026 | J4: Class
A5: Segment name as reported | B5: E&T | C5: E&T | D5: E&T | E5: E&T | F5: E&T | G5: P&E | H5: P&E | I5: P&E | J5: SOURCED
A6: Segment sales | B6: 7187 | C6: 7649 | D6: 6568 | E6: 7836 | F6: 8397 | G6: 9400 | H6: 7031 | I6: 8238 | J6: SOURCED
A7: Prior-year (as shown in release) | B7: 6859 | C7: 7669 | D7: 6681 | E7: 7337 | F7: 7187 | G7: 7649 | H7: 5783 | I7: 7037 | J7: SOURCED (E7: BACK-SOLVED)
A8: Change (calc) | B8: =B6-B7 -> 328 | C8: =C6-C7 -> -20 | D8: =D6-D7 -> -113 | E8: =E6-E7 -> 499 | F8: =F6-F7 -> 1210 | G8: =G6-G7 -> 1751 | H8: =H6-H7 -> 1248 | I8: =I6-I7 -> 1201 | J8: CALC
A9: Volume | B9: 57 | C9: -301 | D9: -175 | E9: 326 | F9: 870 | G9: 1380 | H9: 840 | I9: 736 | J9: SOURCED
A10: Price realization | B10: 213 | C10: 221 | D10: 155 | E10: 139 | F10: 132 | G10: 166 | H10: 108 | I10: 212 | J10: SOURCED
A11: Currency | B11: -20 | C11: 8 | D11: -69 | E11: 15 | F11: 52 | G11: 64 | H11: 111 | I11: 53 | J11: SOURCED
A12: Inter-segment | B12: 78 | C12: 52 | D12: -24 | E12: 19 | F12: 156 | G12: 141 | H12: 189 | I12: 200 | J12: SOURCED
A13: Sum of components (calc) | B13: =SUM(B9:B12) -> 328 | C13: =SUM(C9:C12) -> -20 | D13: =SUM(D9:D12) -> -113 | E13: =SUM(E9:E12) -> 499 | F13: =SUM(F9:F12) -> 1210 | G13: =SUM(G9:G12) -> 1751 | H13: =SUM(H9:H12) -> 1248 | I13: =SUM(I9:I12) -> 1201 | J13: CALC
A14: RECONCILIATION (must be 0) | B14: =B8-B13 -> 0 | C14: =C8-C13 -> 0 | D14: =D8-D13 -> 0 | E14: =E8-E13 -> 0 | F14: =F8-F13 -> 0 | G14: =G8-G13 -> 0 | H14: =H8-H13 -> 0 | I14: =I8-I13 -> 0 | J14: CALC
A15: Segment profit | B15: 1433 | C15: 1477 | D15: 1314 | E15: 1585 | F15: 1678 | G15: 1841 | H15: 1450 | I15: 2027 | J15: SOURCED
A16: Segment profit margin | B16: 0.199 | C16: 0.193 | D16: 0.2 | E16: 0.202 | F16: 0.2 | G16: 0.196 | H16: 0.206 | I16: 0.246 | J16: SOURCED
A18: Shaded = post-restatement. Q2 2025 prior-year not captured; left blank.
A19: Q2 2024 prior-year of 7,337 is BACK-SOLVED: Q2 2025 sales less the four disclosed change components. The Q2 2025 reconciliation therefore closes by construction; it is not an independent check. Shown in orange.

Sheet Dealer Inventory
A1: Dealer Inventory Change — disclosure is inconsistent across quarters
A2: Four of eight quarters now carry a company-wide dollar figure; two carry a Construction Industries figure. The scope changes mid-series, so the column you read matters.
A3: Quarter | B3: Company-wide $mm | C3: Scope | D3: Disclosed language (verbatim) | E3: Source | F3: Class | G3: CI-specific $mm | H3: Verification
A4: Q3 2024 | C4: Narrative only | D4: "Dealer inventory increased less during the third quarter of 2024 than during the third quarter of 2023." | E4: 3Q24 earnings release | F4: NOT DISCLOSED ($) | H4: Company-wide figure as disclosed; no CI split published.
A5: Q4 2024 | B5: -1300 | C5: Company-wide | D5: "Dealer inventory decreased by $1.3 billion during the fourth quarter of 2024, compared with a decrease of $900 million during the fourth quarter of 2023." | E5: 4Q24 earnings release | F5: SOURCED | H5: Company-wide figure as disclosed; no CI split published.
A6: Q1 2025 | B6: 100 | C6: Company-wide | D6: "Dealer inventory increased by $100 million during the first quarter of 2025, compared with an increase of $1.4 billion during the first quarter of 2024." | E6: 1Q25 earnings release | F6: SOURCED | H6: Company-wide figure as disclosed; no CI split published.
A7: Q2 2025 | C7: Narrative, regional | D7: "Dealer inventory decreased during the second quarter of 2025, while remaining about flat during the second quarter of 2024." (CI North America) | E7: 2Q25 earnings release | F7: NOT DISCLOSED ($) | H7: Company-wide figure as disclosed; no CI split published.
A8: Q3 2025 | C8: Narrative, regional | D8: "Dealer inventory increased during the third quarter of 2025, compared with a decrease during the third quarter of 2024." (CI Asia/Pacific) | E8: 3Q25 earnings release | F8: NOT DISCLOSED ($) | H8: Company-wide figure as disclosed; no CI split published.
A9: Q4 2025 | B9: 0 | C9: Company-wide | D9: "Total dealer inventory remained about flat during the fourth quarter of 2025, compared with a decrease of $1.3 billion during the fourth quarter of 2024." | E9: 4Q25 earnings release | F9: SOURCED | H9: Company-wide figure as disclosed; no CI split published.
A10: Q1 2026 | B10: 2000 | C10: Company-wide AND CI split | D10: 10-Q: "dealer inventory increased $2.0 billion" | 10-Q: "Construction Industries dealer inventory increased by $1.5 billion" | Call (corroborating, CFO Bonfield): "a more typical $1.5 billion increase in the first quarter as compared to a slight decrease in the prior year." | E10: Q1 2026 Form 10-Q, Item 2 MD&A — accession 0000018230-26-000021; corroborated by Q1 2026 earnings call | F10: SOURCED | G10: 1500 | H10: $2.0B company-wide and $1.5B CI both confirmed in the filed 10-Q. Verified by EDGAR full-text search exact-phrase match against the filed document (efts.sec.gov). The phrase is confirmed present in the filing; the surrounding sentence was NOT read, because the 4.6MB primary document truncates before Item 2. SCOPE/PERIOD OF THE $2.0B IS INFERRED (company-wide, three months ended 31 Mar 2026): the amount is sourced, but the filing's period qualifier was not recoverable.
A11: Q2 2026 | C11: CI only | D11: 10-Q: "Construction Industries dealer inventory increased by $400 million" | Call (corroborating): "Dealer inventory increased by about $400 million in Construction Industries." | E11: Q2 2026 Form 10-Q, Item 2 MD&A — accession 0000018230-26-000046; corroborated by Q2 2026 earnings call | F11: SOURCED (CI) | G11: 400 | H11: Confirmed in the filed 10-Q. Verified by EDGAR full-text search exact-phrase match against the filed document (efts.sec.gov). The phrase is confirmed present in the filing; the surrounding sentence was NOT read, because the 4.6MB primary document truncates before Item 2.
A13: SCOPE BREAK: Q4 2024 - Q4 2025 dollars are COMPANY-WIDE. Q1 2026 carries both (company-wide $2.0B and CI $1.5B). Q2 2026 carries CI ONLY ($400M) — no company-wide dollar was located for that quarter.
A14: CONSEQUENCE: no continuous eight-quarter dealer-inventory dollar series exists at either scope. Q1 2026 is the only quarter where both scopes are known, and there the CI build is 75% of the company-wide build.
A15: RESOLVED: the Q1 2026 $2.0B and $1.5B and the Q2 2026 $400M are all confirmed in the filed 10-Qs by exact-phrase match. REMAINING: no company-wide figure for Q2 2026; no CI split for Q4 2024 - Q4 2025.

Sheet Retail Statistics
A1: Rolling 3-Month Retail Sales Statistics — SEPARATE BASIS, do not merge with reported sales
A2: 2025 exhibits: "Reported in dollars and based on unit sales as reported primarily by dealers."
A3: 2026 exhibits: "Reported in PRICE NEUTRAL dollars and based on unit sales as reported by dealers."
A4: The WORDING changed; the CI values did not. The only CI period appearing in BOTH filing vintages is Q2 2025, and it reads UP 2% in each. The same cross-vintage test DOES detect a change in the Power & Energy Total (9% to 10%), so the test is sensitive enough to catch a recast — CI simply did not move.
A5: Consequence: CI retail is treated as price-neutral dollars across all eight quarters. Continuity is PROVEN at Q2 2025 and INFERRED elsewhere. Do NOT describe the CI series as recast or rebased.
A6: Construction Industries | B6: Q3 2024 | C6: Q4 2024 | D6: Q1 2025 | E6: Q2 2025 | F6: Q3 2025 | G6: Q4 2025 | H6: Q1 2026 | I6: Q2 2026 | J6: Class
A7: North America | B7: -0.08 | C7: -0.01 | D7: 0.01 | E7: 0.03 | F7: 0.11 | G7: 0.18 | H7: 0.12 | I7: 0.27 | J7: SOURCED
A8: Latin America | B8: 0.06 | C8: 0.05 | D8: 0.16 | E8: -0.07 | F8: 0.02 | G8: 0.06 | H8: 0.04 | I8: 0.24 | J8: SOURCED
A9: EAME | B9: -0.12 | C9: -0.08 | D9: 0.04 | E9: 0.05 | F9: 0.07 | G9: -0.01 | H9: -0.02 | I9: 0.13 | J9: SOURCED
A10: Asia/Pacific | B10: -0.07 | C10: -0.11 | D10: -0.03 | E10: -0.02 | F10: -0.09 | G10: -0.02 | H10: 0 | I10: 0.08 | J10: SOURCED
A11: World | B11: -0.07 | C11: -0.03 | D11: 0.03 | E11: 0.02 | F11: 0.07 | G11: 0.11 | H11: 0.07 | I11: 0.22 | J11: SOURCED
A13: Energy & Transp. / Power & Energy | B13: Q3 2024 | C13: Q4 2024 | D13: Q1 2025 | E13: Q2 2025 | F13: Q3 2025 | G13: Q4 2025 | H13: Q1 2026 | I13: Q2 2026 | J13: Class
A14: Power Generation | B14: 0.11 | C14: 0.27 | D14: 0.58 | E14: 0.19 | F14: 0.33 | G14: 0.44 | H14: 0.48 | I14: 0.72 | J14: SOURCED
A15: Oil & Gas | B15: 0.1 | C15: -0.13 | D15: -0.23 | E15: 0.04 | F15: 0.19 | G15: 0.36 | H15: 0.16 | I15: 0.06 | J15: SOURCED
A16: Industrial | B16: -0.29 | C16: -0.22 | D16: 0.01 | E16: 0.18 | F16: 0.09 | G16: 0.14 | H16: 0.03 | I16: -0.08 | J16: SOURCED
A17: Transportation | B17: 0.25 | C17: 0.06 | D17: 0.04 | E17: -0.24 | J17: SOURCED
A18: Total | B18: 0.05 | C18: 0.02 | D18: 0.13 | E18: 0.09 | F18: 0.23 | G18: 0.37 | H18: 0.32 | I18: 0.33 | J18: SOURCED
A20: "Transportation" disappears from the sector breakdown after Q2 2025, consistent with the segment reorganisation. Shaded cells are not disclosed, not zero.
A21: Q2 2025 Total reads UP 9% in the 2025 exhibit and UP 10% as the comparative in the 2026 exhibit — the P&E sector mix changed beneath it. This is the control that proves the cross-vintage test works: it moves for P&E and does not move for Construction Industries.

Sheet Cash Flow
A1: Operating Cash Flow and Capital Expenditure — disclosed year-to-date, not per quarter
A2: Caterpillar reports these cumulatively. Quarterly figures would have to be derived by subtraction, which this dataset does not do for you.
A4: Period | B4: Operating cash flow $mm | C4: Capex excl. leased $mm | D4: Equipment leased $mm | E4: Source | F4: Class
A5: Nine months ended 30 Sep 2024 | B5: 8642 | C5: 1285 | D5: 893 | E5: 3Q24 earnings release | F5: SOURCED
A6: Q3 2024 (three months) | B6: 3600 | E6: 3Q24 earnings release | F6: SOURCED
A7: Three months ended 31 Mar 2025 | B7: 1289 | C7: 710 | D7: 208 | E7: 1Q25 earnings release | F7: SOURCED
A8: Six months ended 30 Jun 2025 | B8: 4411 | C8: 1873 | E8: 2Q25 earnings release | F8: SOURCED
A9: Nine months ended 30 Sep 2025 | B9: 8148 | C9: 1923 | D9: 1021 | E9: 3Q25 earnings release | F9: SOURCED
A10: Full year 2025 | B10: 11739 | C10: 2821 | E10: 4Q25 earnings release | F10: SOURCED
A11: Three months ended 31 Mar 2026 | B11: 1870 | C11: 728 | E11: 1Q26 earnings release | F11: SOURCED
A12: Six months ended 30 Jun 2026 | B12: 6241 | C12: 1315 | E12: 2Q26 earnings release | F12: SOURCED
A13: Six months ended 30 Jun 2024 (derived) | B13: =B5-B6 -> 5042 | E13: Derived: 9M 2024 OCF less Q3 2024 standalone OCF | F13: DERIVED
A14: Shaded = not disclosed in the document reviewed. Q4 2024, Q2 2024 and Q4 2025 standalone quarters have no published figure.
A17: DERIVED standalone quarters
A18: Computed by subtracting consecutive year-to-date figures above. Only where both endpoints share the same stated basis.
A19: Quarter | B19: Operating cash flow $mm | C19: Capex excl. leased $mm | D19: Basis check | E19: Class
A20: (Q3 2024 is NOT derived here — its standalone OCF of $3,600M is SOURCED directly, row 6. The 9M-less-Q3 subtraction yields H1 2024, which now sits in row 13 where it cannot be misread as a quarter.)
A21: Q2 2025 | B21: =B8-B7 -> 3122 | C21: =C8-C7 -> 1163 | D21: OCF endpoints both OCF — clean. CAPEX: Q1 stated "excl. leased"; H1 stated "combined" — BASIS MISMATCH, not derived. | E21: DERIVED (OCF only)
A22: Q3 2025 | B22: =B9-B8 -> 3737 | D22: OCF clean. Capex: H1 capex basis ambiguous, so Q3 not derived. | E22: DERIVED (OCF only)
A23: Q4 2025 | B23: =B10-B9 -> 3591 | C23: =C10-C9 -> 898 | D23: OCF clean. Capex: FY basis not explicitly stated; treat the derived capex as provisional. | E23: DERIVED
A24: Q2 2026 | B24: =B12-B11 -> 4371 | C24: =C12-C11 -> 587 | D24: Both endpoints stated "excluding equipment leased to others" — clean on both lines. | E24: DERIVED
A26: Q3 2024 standalone OCF of $3,600M is SOURCED directly (row 6), so it is not derived. Q4 2024 and Q2 2024 standalone OCF cannot be derived — no compatible YTD endpoints.
A27: Free cash flow NOT derived: Caterpillar's FCF definition and the treatment of equipment leased to others are not consistently stated across these releases.

Sheet Comparability Log
A1: Comparability Log — every definitional break found while building this dataset
A3: # | B3: Issue | C3: Quarter first seen | D3: Evidence | E3: Effect on the dataset | F3: Treatment here
A4: 1 | B4: Segment renamed | C4: Q4 2025 | D4: Reported as "Energy & Transportation" through Q3 2025; "Power & Energy" from Q4 2025. | E4: Series label changes mid-dataset. | F4: Both names carried on the Power and Energy tab.
A5: 2 | B5: Segment RESTATED | C5: Q1 2026 | D5: Q1 2025 RI reported as 2,884 in the 1Q25 release but 3,661 as the comparative in the 1Q26 release. Q2 2025 RI: 3,087 vs 3,886. P&E moves down by almost the same amount. | E5: Roughly $800M/quarter shifted from E&T/P&E into RI. RI and P&E series are NOT continuous. | F5: Two vintages kept separate; post-restatement columns shaded.
A6: 3 | B6: CI unaffected | C6: — | D6: CI Q1 2025 is 5,184 in both the 1Q25 and 1Q26 releases; Q2 2025 is 6,190 in both. | E6: Construction Industries is safe to chart as one continuous series. | F6: No split needed. Noted in green on the CI tab.
A7: 4 | B7: Resource Industries minor recast | C7: Q3 2025 | D7: Q3 2024 RI reported as 3,028 in the 3Q24 release, 3,048 as the comparative in the 3Q25 release. Q4 2024: 2,962 vs 2,980. | E7: A second, smaller recast predating the big one. | F7: Both figures shown; difference is ~$20M.
A8: 5 | B8: Retail statistics basis wording changed | C8: Q1 2026 | D8: 2025: "Reported in dollars and based on unit sales as reported primarily by dealers." 2026: "Reported in PRICE NEUTRAL dollars..." | E8: Reads like a basis change. It is NOT. The only CI period appearing in BOTH filing vintages is Q2 2025, and it reads UP 2% in each. The same cross-vintage test DOES detect a change in the Power & Energy Total (9% to 10%), so the test is sensitive enough to catch a recast — CI simply did not move. | F8: CI retail treated as price-neutral dollars across all eight quarters; PROVEN at Q2 2025, INFERRED elsewhere. See item 14.
A9: 6 | B9: Retail sector list changed | C9: Q3 2025 | D9: "Transportation" appears as an E&T retail sector through Q2 2025 and is absent thereafter. | E9: The sector Total is not comparable across the break — Q2 2025 reads 9% in the 2025 exhibit, 10% in the 2026 one. | F9: Transportation row ends Q2 2025; cells left blank, not zero.
A10: 7 | B10: Dealer inventory dollars sporadic | C10: throughout | D10: Company-wide dollar figures appear in Q4 2024, Q1 2025, Q4 2025 and Q1 2026. CI dollar figures appear in Q1 2026 and Q2 2026 only (both in the 10-Qs, corroborated on the calls). | E10: No continuous dollar series is possible. | F10: Dealer Inventory tab shows exactly what exists; gaps left empty.
A11: 8 | B11: Cash flow is year-to-date | C11: throughout | D11: Operating cash flow and capex are reported cumulatively, not per quarter. | E11: Quarterly figures require subtraction and are not provided here. | F11: Cash Flow tab reports the periods as published.
A12: 9 | B12: Dealer inventory scope changes mid-series | C12: Q1 2026 | D12: Q4 2024 / Q1 2025 / Q4 2025 disclose a COMPANY-WIDE dollar change. Q1 2026 discloses both scopes. Q2 2026 discloses a CONSTRUCTION INDUSTRIES figure only. | E12: The two are different scopes; charting them as one line would be wrong. | F12: Separate columns on the Dealer Inventory tab.
A13: 10 | B13: CFO changed between Q1 and Q2 2026 | C13: Q2 2026 | D13: Q1 2026 call remarks are attributed to Andrew R. Bonfield; Q2 2026 call remarks to Kyle Epley. | E13: No effect on figures; affects quote attribution only. | F13: Speaker named on each quote.
A14: 11 | B14: Capex basis inconsistent in YTD disclosures | C14: Q2 2025 | D14: Q1 2025 capex stated "excluding equipment leased"; the H1 2025 figure is stated as combined. | E14: Standalone Q2 2025 capex cannot be derived without mixing bases. | F14: Not derived. Left blank with the reason recorded.
A15: 12 | B15: Gap metric basis differences — REVISED 2 Oct (earlier version was wrong) | C15: analytical | D15: Ex 99.2 (2Q 2026): CI retail is "Reported in price neutral dollars and based on unit sales as reported by dealers." The earlier version of this entry said retail was unit-based and that product mix contaminates the gap. | E15: CORRECTED: both sides of the gap are price-neutral dollar measures of unit sales, so product MIX is represented on both sides and should largely CANCEL rather than systematically contaminate the gap. The remaining basis differences are: current-price vs price-neutral treatment of the disclosed inventory dollars; parts and services included in reported sales with no counterpart in the retail machine series; currency treatment, which is unresolved; and other unresolved scope differences. | F15: The gap is described as an ESTIMATE OF THE DIRECTION AND RELATIVE SIZE of dealer stocking, never as an exact dollar measurement. Disclosed dealer-inventory dollars are shown alongside it wherever they exist.
A16: 13 | B16: Dealer-inventory dollars verified by phrase match, not by reading the sentence | C16: method | D16: The 10-Q primary documents are ~4.6MB and truncate before Item 2 on every retrieval attempt. The Q1/Q2 2026 dealer-inventory dollars were confirmed instead by EDGAR full-text search exact-phrase match (efts.sec.gov) against the filed accession. | E16: Presence of the phrase in the filing is confirmed. The surrounding sentence — comparatives, period qualifiers, any offsetting commentary — has NOT been read. | F16: Figures carry the verbatim matched phrase and the accession number. Scope/period is marked INFERRED wherever the qualifier was not recoverable.
A17: 14 | B17: Retail basis WORDING changed for 2026; values did not | C17: disclosure | D17: 2Q25 Ex 99.2: CI "Reported in dollars and based on unit sales as reported primarily by dealers." 2Q26 Ex 99.2: CI "Reported in price neutral dollars and based on unit sales as reported by dealers." | E17: Reads like a basis change. It is not. The only CI period appearing in BOTH filing vintages is Q2 2025, and it reads UP 2% in each. The same cross-vintage test DOES detect a change in the Power & Energy Total (9% to 10%), so the test is sensitive enough to catch a recast — CI simply did not move. | F17: Treated as a clarification, not a recast. The separate 2026 realignment note concerns Rail / Resource Industries and Industrial, NOT Construction Industries.
A18: 15 | B18: Q4 2025 CI margin depressed by manufacturing costs largely attributed to tariffs | C18: analytical | D18: 4Q25 release, CI: "unfavorable manufacturing costs of $420 million ... largely reflected the impact of higher tariffs." 1Q26 release, CI: $362 million, same attribution. 2Q26 call, CFO Kyle Epley: CI margin "impacted by ... 340 basis points within Construction Industries." Exact release wording INSUFFICIENT EVIDENCE: the CI tab (A28) quotes "...higher tariff costs."; re-check against the releases. | E18: Our reading (INTERPRETIVE): reported CI margin of 14.9% in Q4 2025 was mainly a tariff cost shock rather than demand weakness or operating deterioration; the disclosed manufacturing costs only 'largely' reflected tariffs. Ex-tariff it sits near 20.9%, inside the 19.6-20.4% band of the surrounding quarters. Using the reported series as a baseline overstates the 2026 recovery. | F18: Ex-tariff margin shown on the Analysis tab for all three quarters (Q2 2026 on a different method). NOT a one-time item: tariffs recur while in force. FY2026 tariff guidance (about $2.2bn, roughly half of Q3 in CI) was recorded without a verbatim quote: INSUFFICIENT EVIDENCE, not used in the analysis.
A19: 16 | B19: Q2 2026 holds a one-time IEEPA tariff recovery | C19: disclosure | D19: Q2 2026 release: "Operating profit in the second quarter of 2026 included $392 million of expected International Emergency Economic Power Act (IEEPA) tariff recoveries." Call, CFO Kyle Epley: "with the majority of this amount reflected in corporate items." | E19: A one-time credit of this size would inflate Q2 2026 margins if it sat in the segments. The CFO said the majority is in corporate items; the CI share was not disclosed, so CI margin is unlikely to be materially affected (INFERENCE). | F19: Consolidated operating margin for Q2 2026 must be described as including a one-time recovery. The CI share of the $392M was not disclosed; with the majority in corporate items, CI segment margin is unlikely to be materially affected (INFERENCE; no adjustment made). CI tariff COST of 340 bps is separate and still a drag.

Sheet Source Index
A1: Source Index — every document used
A3: Quarter | B3: Document | C3: URL | D3: Used for
A4: Q3 2024 | B4: 3Q 2024 Earnings Release | C4: https://www.caterpillar.com/content/dam/caterpillarDotCom/releases/3q24/3q24-caterpillar-inc-financial-results.pdf | D4: Consolidated, segments, cash flow, dealer narrative
A5: Q4 2024 | B5: 4Q 2024 Earnings Release | C5: https://www.caterpillar.com/content/dam/caterpillarDotCom/releases/4q24/4q24-caterpillar-inc-financial-results.pdf | D5: Consolidated, segments, dealer inventory $
A6: Q1 2025 | B6: 1Q 2025 Earnings Release | C6: https://www.caterpillar.com/content/dam/caterpillarDotCom/releases/1q25/1q25-caterpillar-inc-financial-results.pdf | D6: Consolidated, segments, cash flow, dealer inventory $
A7: Q2 2025 | B7: 2Q 2025 Earnings Release | C7: https://www.caterpillar.com/content/dam/caterpillarDotCom/releases/2q25/2q25-caterpillar-inc-financial-results.pdf | D7: Consolidated, segments, cash flow, dealer narrative
A8: Q3 2025 | B8: 3Q 2025 Earnings Release | C8: https://www.caterpillar.com/content/dam/caterpillarDotCom/releases/3q25/3q25-caterpillar-inc-financial-results.pdf | D8: Consolidated, segments, cash flow, dealer narrative
A9: Q4 2025 | B9: 4Q 2025 Earnings Release | C9: https://www.caterpillar.com/content/dam/caterpillarDotCom/releases/4q25/4q25-caterpillar-inc-financial-results.pdf | D9: Consolidated, segments, dealer inventory $
A10: Q1 2026 | B10: 1Q 2026 Earnings Release | C10: https://www.caterpillar.com/content/dam/caterpillarDotCom/releases/1q26/1q26-caterpillar-inc-financial-results.pdf | D10: Consolidated, segments, cash flow
A11: Q2 2026 | B11: 2Q 2026 Earnings Release | C11: https://www.caterpillar.com/content/dam/caterpillarDotCom/releases/2q26/2q26-caterpillar-inc-financial-results.pdf | D11: Consolidated, segments, cash flow
A12: Q2 2025 | B12: Ex 99.2 Retail Sales Statistics | C12: https://www.sec.gov/Archives/edgar/data/18230/000001823025000037/ex992toformcat2q2025retail.htm | D12: Retail statistics Q3 2024 – Q2 2025, 2025 basis note
A13: Q2 2026 | B13: Ex 99.2 Retail Sales Statistics | C13: https://www.sec.gov/Archives/edgar/data/18230/000001823026000040/ex992toformcat2q2026retail.htm | D13: Retail statistics Q2 2025 – Q2 2026, 2026 basis note
A14: Q2 2026 | B14: Ex 99.1 Earnings Release (SEC) | C14: https://www.sec.gov/Archives/edgar/data/18230/000001823026000040/ex991toformcat2q2026earnin.htm | D14: Segment price realization
... A24: Q2 2026 | B24: Q2 2026 Earnings Call Transcript | C24: https://www.fool.com/earnings/call-transcripts/2026/08/11/caterpillar-cat-q2-2026-earnings-call-transcript/ | D24: CI tariff impact 340 bps; IEEPA $392M, majority in corporate items. FY26 tariff cost ~$2.2B: no verbatim quote captured, INSUFFICIENT EVIDENCE.
