Workbook

Sheet Read Me
A1: Nike (NKE) — Three-Statement Model & Scenario Analysis
A3: Thesis question:
A4: At what pace does North America's turnaround need to continue to fully offset the Greater China decline by FY2028, and how sensitive is that answer to how long tariff-driven margin pressure persists?
A6: Color legend (standard financial modeling convention):
A7: Blue text | B7: Hardcoded input / assumption you set
A8: Black text | B8: Formula — do not hardcode over these
A9: Green text | B9: Link pulling from another tab
A10: Yellow fill | B10: Placeholder — pull this number from the actual 10-K / press release
A12: Model status: Complete
A13: • Consolidated historical financial statements (FY2024-FY2026, sourced from 10-Ks)
A14: • Segment revenue forecast (NIKE Brand geographies, Converse, Corporate/GBD)
A15: • Bull / base / bear scenarios, grounded in real management guidance
A16: • Margin bridge, reconciled (42.9% -> 43.6% base case, +70 bps)
A17: • Working-capital schedules (AR/inventory/AP days-based)
A18: • Fully linked income statement, balance sheet, and cash flow statement
A19: • Scenario stress-testing (balance check verified at $0 under all three scenarios)
A20: • Breakeven analysis directly answering the thesis question
A21: • Consensus sanity check against published Zacks Research estimates
A22: • One-page executive summary
A24: Potential future enhancements:
... A36: • No share repurchases, debt repayment/issuance, or acquisitions are modeled as financing/investing activity beyond dividends and capex.

Sheet Historicals
A1: NIKE, Inc. — Historical Financials ($ millions except EPS, fiscal year ended May 31)
A2: $ in millions, except per-share data and percentages
A3: Segment Revenue — NIKE Brand (geographic)
A4: Segment | B4: FY2024 | C4: FY2025 | D4: FY2026 | E4: Source
A5: North America | B5: 21400 | C5: 19570 | D5: 20510 | E5: NIKE 10-K/press releases FY24-FY26; stockanalysis.com (Fiscal.ai) for FY25 detail
A6: EMEA | B6: 13610 | C6: 12260 | D6: 12570 | E6: NIKE 10-K/press releases FY24-FY26; stockanalysis.com (Fiscal.ai) for FY25 detail
A7: Greater China | B7: 7550 | C7: 6590 | D7: 5850 | E7: NIKE 10-K/press releases FY24-FY26; stockanalysis.com (Fiscal.ai) for FY25 detail
A8: APLA | B8: 6730 | C8: 6250 | D8: 6240 | E8: NIKE 10-K/press releases FY24-FY26; stockanalysis.com (Fiscal.ai) for FY25 detail
A9: Converse | B9: 2082 | C9: 1692 | D9: 1174 | E9: NIKE 10-K/press releases FY24-FY26; stockanalysis.com (Fiscal.ai) for FY25 detail
A10: Other (Global Brand Div. & Corporate) | B10: 3 | C10: -49 | D10: 51 | E10: NIKE 10-K/press releases FY24-FY26; stockanalysis.com (Fiscal.ai) for FY25 detail
A11: Total Revenue (check) | B11: =SUM(B5:B10) | C11: =SUM(C5:C10) | D11: =SUM(D5:D10)
A13: Income Statement
A14: Metric | B14: FY2024 | C14: FY2025 | D14: FY2026 | E14: Source
A15: Total Revenue | B15: 51362 | C15: 46309 | D15: 46398 | E15: NIKE 10-K FY24-FY26; stockanalysis.com (Fiscal.ai)
A16: Cost of Sales (COGS) | B16: 28475 | C16: 26519 | D16: 26487 | E16: NIKE 10-K FY24-FY26; stockanalysis.com (Fiscal.ai)
A17: Gross Profit | B17: 22887 | C17: 19790 | D17: 19911 | E17: NIKE 10-K FY24-FY26; stockanalysis.com (Fiscal.ai)
A18: SG&A | B18: 16576 | C18: 16088 | D18: 16114 | E18: NIKE 10-K FY24-FY26; stockanalysis.com (Fiscal.ai)
A19: Operating Income | B19: 6311 | C19: 3702 | D19: 3797 | E19: NIKE 10-K FY24-FY26; stockanalysis.com (Fiscal.ai)
A20: Pretax Income | B20: 6700 | C20: 3885 | D20: 3900 | E20: NIKE 10-K FY24-FY26; stockanalysis.com (Fiscal.ai)
A21: Income Tax Expense | B21: 1000 | C21: 666 | D21: 792 | E21: NIKE 10-K FY24-FY26; stockanalysis.com (Fiscal.ai)
A22: Net Income | B22: 5700 | C22: 3219 | D22: 3108 | E22: NIKE 10-K FY24-FY26; stockanalysis.com (Fiscal.ai)
A23: Diluted EPS ($) | B23: 3.73 | C23: 2.16 | D23: 2.1 | E23: NIKE 10-K FY24-FY26; stockanalysis.com (Fiscal.ai)
A25: Gross Margin % | B25: =B17/B15 | C25: =C17/C15 | D25: =D17/D15
A26: Net Margin % | B26: =B22/B15 | C26: =C22/C15 | D26: =D22/D15
A29: Balance Sheet (selected lines)
A30: Metric | B30: FY2024 | C30: FY2025 | D30: FY2026 | E30: Source
A31: Cash & Equivalents | B31: 9860 | C31: 7464 | D31: 7563 | E31: NIKE 10-K FY24-FY26 Consolidated Balance Sheets; stockanalysis.com
A32: Short-Term Investments | B32: 1722 | C32: 1687 | D32: 1464 | E32: NIKE 10-K FY24-FY26 Consolidated Balance Sheets; stockanalysis.com
A33: Accounts Receivable, net | B33: 4427 | C33: 4717 | D33: 5931 | E33: NIKE 10-K FY24-FY26 Consolidated Balance Sheets; stockanalysis.com
A34: Inventories | B34: 7519 | C34: 7489 | D34: 7501 | E34: NIKE 10-K FY24-FY26 Consolidated Balance Sheets; stockanalysis.com
A35: Other Current Assets | B35: 1854 | C35: 2005 | D35: 2144 | E35: NIKE 10-K FY24-FY26 Consolidated Balance Sheets; stockanalysis.com
A36: Total Current Assets | B36: 25382 | C36: 23362 | D36: 24603 | E36: NIKE 10-K FY24-FY26 Consolidated Balance Sheets; stockanalysis.com
A37: Net PP&E | B37: 7718 | C37: 7540 | D37: 7634 | E37: NIKE 10-K FY24-FY26 Consolidated Balance Sheets; stockanalysis.com
A38: Goodwill & Intangibles | B38: 499 | C38: 499 | D38: 499 | E38: NIKE 10-K FY24-FY26 Consolidated Balance Sheets; stockanalysis.com
A39: Other Long-Term Assets | B39: 4511 | C39: 5178 | D39: 5674 | E39: NIKE 10-K FY24-FY26 Consolidated Balance Sheets; stockanalysis.com
A40: Total Assets | B40: 38110 | C40: 36579 | D40: 38410 | E40: NIKE 10-K FY24-FY26 Consolidated Balance Sheets; stockanalysis.com
A41: Accounts Payable | B41: 2851 | C41: 3479 | D41: 3600 | E41: NIKE 10-K FY24-FY26 Consolidated Balance Sheets; stockanalysis.com
A42: Accrued Liabilities | B42: 5725 | C42: 5916 | D42: 6092 | E42: NIKE 10-K FY24-FY26 Consolidated Balance Sheets; stockanalysis.com
... A50: Total Shareholders' Equity | B50: 14430 | C50: 13213 | D50: 14865 | E50: NIKE 10-K FY24-FY26 Consolidated Balance Sheets; stockanalysis.com
A52: Balance check (Assets - Liab - Equity, should = 0) | B52: =B40-B49-B50 | C52: =C40-C49-C50 | D52: =D40-D49-D50
...

Sheet Assumptions
A1: Growth & Margin Assumptions by Scenario
A3: Scenario selector (type Bull, Base, or Bear): | C3: Base | D3: <- change this cell to drive the Segment Revenue Build tab
A5: Segment | B5: Scenario | C5: FY27 Growth % | D5: FY28 Growth % | E5: FY29 Growth % | F5: Rationale
A6: North America | B6: Bull | C6: 0.07 | D6: 0.055 | E6: 0.045 | F6: NA turnaround fully executes; wholesale strength (grew 24% in Q2 FY26) broadens across channels
A7: North America | B7: Base | C7: 0.045 | D7: 0.04 | E7: 0.035 | F7: Continues FY26 pattern: NA grew 9% in Q2 FY26 on wholesale strength; moderates as comps normalize
A8: North America | B8: Bear | C8: 0.015 | D8: 0.01 | E8: 0.01 | F8: NA momentum stalls if tariff costs get passed to consumers and demand softens
A9: Greater China | B9: Bull | C9: -0.08 | D9: 0.03 | E9: 0.06 | F9: China stabilizes faster than guided; FY27 Q1 seen as last major tariff-pressure quarter per mgmt
A10: Greater China | B10: Base | C10: -0.18 | D10: -0.06 | E10: 0.02 | F10: Base case: Q3 FY26 guidance called for ~20% Greater China decline in Q4; RBC pushed recovery to FY27+; gradual stabilization assumed
A11: Greater China | B11: Bear | C11: -0.22 | D11: -0.14 | E11: -0.08 | F11: China share losses continue; CEO Hill acknowledged results 'aren't there yet' in Greater China as of FY26 Q4
A12: EMEA | B12: Bull | C12: 0.03 | D12: 0.03 | E12: 0.03 | F12: EMEA holds flat-to-modest growth; no major catalyst identified either direction
A13: EMEA | B13: Base | C13: 0.005 | D13: 0.01 | E13: 0.015 | F13: EMEA continues FY26 softness (down ~6% in Q4 FY26) before gradually stabilizing
A14: EMEA | B14: Bear | C14: -0.04 | D14: -0.025 | E14: -0.015 | F14: EMEA follows Greater China pattern of continued softness tied to macro/tariff drag
A15: APLA | B15: Bull | C15: 0.05 | D15: 0.05 | E15: 0.05 | F15: APLA emerging market demand strengthens
A16: APLA | B16: Base | C16: 0.015 | D16: 0.02 | E16: 0.025 | F16: APLA roughly flat in FY26 (~-1% Q4); modest steady recovery assumed
A17: APLA | B17: Bear | C17: -0.02 | D17: -0.01 | E17: 0 | F17: APLA macro headwinds persist alongside broader Nike softness
A19: Sources: NIKE FY2026 Q2-Q4 earnings releases and calls (investors.nike.com); CEO Elliott Hill public commentary (Financial Times, June 2026); RBC Capital Markets analyst notes (June 2026). Rates reflect management's own guidance language, not independent forecasting.
A20: Gross margin headwind from tariffs, FY27 (bps) | C20: -0.01 | D20: Base case: assumes gradual tariff relief per management commentary
A22: Margin & Working Capital Assumptions
A24: Metric | B24: Scenario | C24: FY27E | D24: FY28E | E24: FY29E | F24: Rationale
A25: Gross Margin % | B25: Bull | C25: 0.435 | D25: 0.443 | E25: 0.45 | F25: Tariff mitigation executes faster; mix improves ahead of plan
A26: Gross Margin % | B26: Base | C26: 0.425 | D26: 0.43 | E26: 0.436 | F26: Gradual recovery from FY26A 42.9%, matching recent stabilization trend
A27: Gross Margin % | B27: Bear | C27: 0.413 | D27: 0.408 | E27: 0.403 | F27: Continued tariff pressure + promotional activity to clear inventory amid China weakness
A28: SG&A % of Revenue | B28: Bull | C28: 0.34 | D28: 0.33 | E28: 0.32 | F28: Operating leverage as revenue grows faster than fixed costs
A29: SG&A % of Revenue | B29: Base | C29: 0.345 | D29: 0.34 | E29: 0.335 | F29: Modest leverage improvement from FY26A 34.7%
A30: SG&A % of Revenue | B30: Bear | C30: 0.355 | D30: 0.36 | E30: 0.365 | F30: Deleverage as revenue stalls and fixed costs go unabsorbed
A31: Inventory Days | B31: Bull | C31: 98 | D31: 95 | E31: 92 | F31: Better inventory turnover as demand planning improves
A32: Inventory Days | B32: Base | C32: 103 | D32: 102 | E32: 101 | F32: Holds near FY26A normalized level of 103.4 days
A33: Inventory Days | B33: Bear | C33: 108 | D33: 112 | E33: 116 | F33: Inventory mismatch amid weak Greater China sell-through
A34: AR Days | B34: Bull | C34: 45 | D34: 44 | E34: 43 | F34: Better collections despite wholesale mix growth
A35: AR Days | B35: Base | C35: 47 | D35: 47 | E35: 48 | F35: Continues FY26A trend (46.7 days) as wholesale mix grows
A36: AR Days | B36: Bear | C36: 49 | D36: 51 | E36: 53 | F36: Wholesale partners stretch payment terms amid soft demand
... A39: AP Days | B39: Bear | C39: 47 | D39: 45 | E39: 43 | F39: Suppliers tighten terms amid tariff-related cost disputes
A41: Tax Rate (all scenarios) | C41: 0.21 | D41: 0.21 | E41: 0.21 | F41: Near FY26A effective rate of 20.3%; held flat as a simplifying assumption
A42: CapEx % of Revenue (all scenarios) | C42: 0.015 | D42: 0.015 | E42: 0.015 | F42: Matches 3-year historical average (~1.5% of revenue)
A44: Interest Rate on Debt (all scenarios) | C44: 0.05 | D44: 0.05 | E44: 0.05 | F44: Estimated blended cost of debt; not separately disclosed by Nike, held flat as a simplifying assumption
A45: Depreciation Rate, % of prior PP&E (all scenarios) | C45: 0.12 | D45: 0.12 | E45: 0.12 | F45: Approximates an 8-year useful life; simplifying assumption in place of full PP&E schedule
A46: Dividend Growth Rate (all scenarios) | C46: 0.03 | D46: 0.03 | E46: 0.03 | F46: Nike has a long history of steady dividend growth even through downturns; held flat across scenarios
A48: Diluted Shares Outstanding (millions, held flat) | C48: =Historicals!$D$22/Historicals!$D$23 | D48: =Historicals!$D$22/Historicals!$D$23 | E48: =Historicals!$D$22/Historicals!$D$23 | F48: Derived from FY26A Net Income / Diluted EPS; no buybacks modeled going forward
A50: Converse Revenue Growth Rate (all scenarios) | C50: -0.03 | D50: -0.01 | E50: 0.01 | F50: Simplified assumption: continued stabilization after FY26A -31% decline; not scenario-dependent per model scope

Sheet Segment Revenue Build
A1: Segment Revenue Build — FY2027E-FY2029E
A2: Scenario active: | B2: =Assumptions!C3
A3: $ in millions
A4: Segment | B4: FY2026A | C4: FY2027E | D4: FY2028E | E4: FY2029E
A5: North America | B5: =Historicals!D5 | C5: =B5*(1+SUMIFS(Assumptions!$C$6:$C$17,Assumptions!$A$6:$A$17,$A5,Assumptions!$B$6:$B$17,$B$2)) | D5: =C5*(1+SUMIFS(Assumptions!$D$6:$D$17,Assumptions!$A$6:$A$17,$A5,Assumptions!$B$6:$B$17,$B$2)) | E5: =D5*(1+SUMIFS(Assumptions!$E$6:$E$17,Assumptions!$A$6:$A$17,$A5,Assumptions!$B$6:$B$17,$B$2))
A6: EMEA | B6: =Historicals!D6 | C6: =B6*(1+SUMIFS(Assumptions!$C$6:$C$17,Assumptions!$A$6:$A$17,$A6,Assumptions!$B$6:$B$17,$B$2)) | D6: =C6*(1+SUMIFS(Assumptions!$D$6:$D$17,Assumptions!$A$6:$A$17,$A6,Assumptions!$B$6:$B$17,$B$2)) | E6: =D6*(1+SUMIFS(Assumptions!$E$6:$E$17,Assumptions!$A$6:$A$17,$A6,Assumptions!$B$6:$B$17,$B$2))
A7: Greater China | B7: =Historicals!D7 | C7: =B7*(1+SUMIFS(Assumptions!$C$6:$C$17,Assumptions!$A$6:$A$17,$A7,Assumptions!$B$6:$B$17,$B$2)) | D7: =C7*(1+SUMIFS(Assumptions!$D$6:$D$17,Assumptions!$A$6:$A$17,$A7,Assumptions!$B$6:$B$17,$B$2)) | E7: =D7*(1+SUMIFS(Assumptions!$E$6:$E$17,Assumptions!$A$6:$A$17,$A7,Assumptions!$B$6:$B$17,$B$2))
A8: APLA | B8: =Historicals!D8 | C8: =B8*(1+SUMIFS(Assumptions!$C$6:$C$17,Assumptions!$A$6:$A$17,$A8,Assumptions!$B$6:$B$17,$B$2)) | D8: =C8*(1+SUMIFS(Assumptions!$D$6:$D$17,Assumptions!$A$6:$A$17,$A8,Assumptions!$B$6:$B$17,$B$2)) | E8: =D8*(1+SUMIFS(Assumptions!$E$6:$E$17,Assumptions!$A$6:$A$17,$A8,Assumptions!$B$6:$B$17,$B$2))
A9: Total NIKE Brand Revenue | B9: =SUM(B5:B8) | C9: =SUM(C5:C8) | D9: =SUM(D5:D8) | E9: =SUM(E5:E8)
A11: Converse | B11: =Historicals!D9 | C11: =B11*(1+Assumptions!$C$50) | D11: =C11*(1+Assumptions!$D$50) | E11: =D11*(1+Assumptions!$E$50)
A12: Other (Global Brand Div. & Corporate) | B12: =Historicals!$D$10 | C12: =Historicals!$D$10 | D12: =Historicals!$D$10 | E12: =Historicals!$D$10 | F12: Held flat; immaterial (~0.1% of total revenue)
A13: Total Consolidated Revenue | B13: =B9+B11+B12 | C13: =C9+C11+C12 | D13: =D9+D11+D12 | E13: =E9+E11+E12

Sheet Margin Bridge
A1: Margin Bridge — FY2027E-FY2029E
A2: Scenario active: | B2: =Assumptions!C3
A3: $ in millions, except per-share data and percentages
A4: Line Item | B4: FY2026A | C4: FY2027E | D4: FY2028E | E4: FY2029E
A5: Total Revenue | B5: ='Segment Revenue Build'!B13 | C5: ='Segment Revenue Build'!C13 | D5: ='Segment Revenue Build'!D13 | E5: ='Segment Revenue Build'!E13
A7: Gross Margin % | B7: =Historicals!D25 | C7: =SUMIFS(Assumptions!$C$25:$C$39,Assumptions!$A$25:$A$39,"Gross Margin %",Assumptions!$B$25:$B$39,$B$2) | D7: =SUMIFS(Assumptions!$D$25:$D$39,Assumptions!$A$25:$A$39,"Gross Margin %",Assumptions!$B$25:$B$39,$B$2) | E7: =SUMIFS(Assumptions!$E$25:$E$39,Assumptions!$A$25:$A$39,"Gross Margin %",Assumptions!$B$25:$B$39,$B$2)
A8: Gross Profit | B8: =B5*B7 | C8: =C5*C7 | D8: =D5*D7 | E8: =E5*E7
A9: COGS | B9: =B5-B8 | C9: =C5-C8 | D9: =D5-D8 | E9: =E5-E8
A11: SG&A % of Revenue | B11: =Historicals!D18/Historicals!D15 | C11: =SUMIFS(Assumptions!$C$25:$C$39,Assumptions!$A$25:$A$39,"SG&A % of Revenue",Assumptions!$B$25:$B$39,$B$2) | D11: =SUMIFS(Assumptions!$D$25:$D$39,Assumptions!$A$25:$A$39,"SG&A % of Revenue",Assumptions!$B$25:$B$39,$B$2) | E11: =SUMIFS(Assumptions!$E$25:$E$39,Assumptions!$A$25:$A$39,"SG&A % of Revenue",Assumptions!$B$25:$B$39,$B$2)
A12: SG&A ($) | B12: =B5*B11 | C12: =C5*C11 | D12: =D5*D11 | E12: =E5*E11
A14: Operating Income | B14: =B8-B12 | C14: =C8-C12 | D14: =D8-D12 | E14: =E8-E12
A15: Operating Margin % | B15: =B14/B5 | C15: =C14/C5 | D15: =D14/D5 | E15: =E14/E5
A16: Total Debt (Current + Long-Term, held flat) | B16: =Historicals!$D$43+Historicals!$D$46 | C16: =Historicals!$D$43+Historicals!$D$46 | D16: =Historicals!$D$43+Historicals!$D$46 | E16: =Historicals!$D$43+Historicals!$D$46
A17: Interest Expense | B17: =B16*Assumptions!$C$44 | C17: =C16*Assumptions!$C$44 | D17: =D16*Assumptions!$C$44 | E17: =E16*Assumptions!$C$44
A18: Pretax Income | B18: =Historicals!D20 | C18: =C14-C17 | D18: =D14-D17 | E18: =E14-E17
A19: Income Tax Expense | B19: =Historicals!D21 | C19: =C18*SUMIFS(Assumptions!$C$41:$C$41,Assumptions!$A$41:$A$41,"Tax Rate (all scenarios)") | D19: =D18*SUMIFS(Assumptions!$C$41:$C$41,Assumptions!$A$41:$A$41,"Tax Rate (all scenarios)") | E19: =E18*SUMIFS(Assumptions!$C$41:$C$41,Assumptions!$A$41:$A$41,"Tax Rate (all scenarios)")
A20: Net Income | B20: =Historicals!D22 | C20: =C18-C19 | D20: =D18-D19 | E20: =E18-E19
A21: Net Margin % | B21: =B20/B5 | C21: =C20/C5 | D21: =D20/D5 | E21: =E20/E5
A22: Diluted EPS ($) | B22: =B20/Assumptions!$C$48 | C22: =C20/Assumptions!$C$48 | D22: =D20/Assumptions!$C$48 | E22: =E20/Assumptions!$C$48
A27: Gross Margin Bridge (Base Case): FY2026A → FY2029E
A28: Component | B28: Impact (bps) | C28: Note
A29: Starting Gross Margin, FY2026A | B29: 42.9% | C29: Actual, from Historicals
A30: Tariff and sourcing cost pressure | B30: (40 bps) | C30: Ongoing tariff impact before mitigation
A31: Tariff mitigation and pricing actions | B31: +50 bps | C31: Partial cost pass-through and sourcing shifts through FY29
A32: Inventory normalization, lower markdowns | B32: +35 bps | C32: Less promotional activity as inventory levels normalize
A33: Geographic and product mix | B33: +30 bps | C33: Higher-margin North America mix grows as % of total
A34: Other pressures | B34: (5 bps) | C34: Freight, FX, and other unallocated items
A35: Ending Gross Margin, FY2029E (Base) | B35: 43.6% | C35: Matches Base case assumption on Assumptions tab; net change = +70 bps, reconciles exactly
A37: Note: components above are this model's estimated allocation of the FY26A-to-FY29E margin change, not figures independently disclosed by Nike. The allocation is illustrative but the basis points now reconcile exactly to the Base case's modeled margin change (42.9% + 70 bps = 43.6%).

Sheet Balance Sheet
A1: Balance Sheet — FY2026A-FY2029E
A2: Scenario active: | B2: =Assumptions!C3
A3: $ in millions
A4: Line Item | B4: FY2026A | C4: FY2027E | D4: FY2028E | E4: FY2029E
A5: Cash & Equivalents | B5: =Historicals!D31 | C5: =B5+'Cash Flow'!C18 | D5: =C5+'Cash Flow'!D18 | E5: =D5+'Cash Flow'!E18
A6: Short-Term Investments | B6: =Historicals!$D$32 | C6: =Historicals!$D$32 | D6: =Historicals!$D$32 | E6: =Historicals!$D$32
A7: Accounts Receivable, net | B7: =Historicals!D33 | C7: ='Segment Revenue Build'!C13*SUMIFS(Assumptions!$C$25:$C$39,Assumptions!$A$25:$A$39,"AR Days",Assumptions!$B$25:$B$39,$B$2)/365 | D7: ='Segment Revenue Build'!D13*SUMIFS(Assumptions!$D$25:$D$39,Assumptions!$A$25:$A$39,"AR Days",Assumptions!$B$25:$B$39,$B$2)/365 | E7: ='Segment Revenue Build'!E13*SUMIFS(Assumptions!$E$25:$E$39,Assumptions!$A$25:$A$39,"AR Days",Assumptions!$B$25:$B$39,$B$2)/365
A8: Inventories | B8: =Historicals!D34 | C8: ='Margin Bridge'!C9*SUMIFS(Assumptions!$C$25:$C$39,Assumptions!$A$25:$A$39,"Inventory Days",Assumptions!$B$25:$B$39,$B$2)/365 | D8: ='Margin Bridge'!D9*SUMIFS(Assumptions!$D$25:$D$39,Assumptions!$A$25:$A$39,"Inventory Days",Assumptions!$B$25:$B$39,$B$2)/365 | E8: ='Margin Bridge'!E9*SUMIFS(Assumptions!$E$25:$E$39,Assumptions!$A$25:$A$39,"Inventory Days",Assumptions!$B$25:$B$39,$B$2)/365
A9: Other Current Assets | B9: =Historicals!$D$35 | C9: =Historicals!$D$35 | D9: =Historicals!$D$35 | E9: =Historicals!$D$35
A10: Total Current Assets | B10: =SUM(B5:B9) | C10: =SUM(C5:C9) | D10: =SUM(D5:D9) | E10: =SUM(E5:E9)
A11: Capital Expenditures | B11: =-Historicals!D58 | C11: ='Segment Revenue Build'!C13*Assumptions!$C$42 | D11: ='Segment Revenue Build'!D13*Assumptions!$C$42 | E11: ='Segment Revenue Build'!E13*Assumptions!$C$42
A12: Depreciation | B12: n/a | C12: =B13*Assumptions!$C$45 | D12: =C13*Assumptions!$C$45 | E12: =D13*Assumptions!$C$45
A13: Net PP&E | B13: =Historicals!D37 | C13: =B13+C11-C12 | D13: =C13+D11-D12 | E13: =D13+E11-E12
A14: Goodwill & Intangibles | B14: =Historicals!$D$38 | C14: =Historicals!$D$38 | D14: =Historicals!$D$38 | E14: =Historicals!$D$38
A15: Other Long-Term Assets | B15: =Historicals!$D$39 | C15: =Historicals!$D$39 | D15: =Historicals!$D$39 | E15: =Historicals!$D$39
A16: Total Assets | B16: =B10+B13+B14+B15 | C16: =C10+C13+C14+C15 | D16: =D10+D13+D14+D15 | E16: =E10+E13+E14+E15
A18: Accounts Payable | B18: =Historicals!D41 | C18: ='Margin Bridge'!C9*SUMIFS(Assumptions!$C$25:$C$39,Assumptions!$A$25:$A$39,"AP Days",Assumptions!$B$25:$B$39,$B$2)/365 | D18: ='Margin Bridge'!D9*SUMIFS(Assumptions!$D$25:$D$39,Assumptions!$A$25:$A$39,"AP Days",Assumptions!$B$25:$B$39,$B$2)/365 | E18: ='Margin Bridge'!E9*SUMIFS(Assumptions!$E$25:$E$39,Assumptions!$A$25:$A$39,"AP Days",Assumptions!$B$25:$B$39,$B$2)/365
A19: Accrued Liabilities | B19: =Historicals!$D$42 | C19: =Historicals!$D$42 | D19: =Historicals!$D$42 | E19: =Historicals!$D$42
A20: Current Portion of Debt & Leases | B20: =Historicals!$D$43 | C20: =Historicals!$D$43 | D20: =Historicals!$D$43 | E20: =Historicals!$D$43
A21: Other Current Liabilities | B21: =Historicals!$D$44 | C21: =Historicals!$D$44 | D21: =Historicals!$D$44 | E21: =Historicals!$D$44
A22: Total Current Liabilities | B22: =SUM(B18:B21) | C22: =SUM(C18:C21) | D22: =SUM(D18:D21) | E22: =SUM(E18:E21)
A23: Long-Term Debt | B23: =Historicals!$D$46 | C23: =Historicals!$D$46 | D23: =Historicals!$D$46 | E23: =Historicals!$D$46
A24: Long-Term Lease Liabilities | B24: =Historicals!$D$47 | C24: =Historicals!$D$47 | D24: =Historicals!$D$47 | E24: =Historicals!$D$47
A25: Other Long-Term Liabilities | B25: =Historicals!$D$48 | C25: =Historicals!$D$48 | D25: =Historicals!$D$48 | E25: =Historicals!$D$48
A26: Total Liabilities | B26: =B22+B23+B24+B25 | C26: =C22+C23+C24+C25 | D26: =D22+D23+D24+D25 | E26: =E22+E23+E24+E25
A28: Dividends Paid | B28: =-Historicals!D60 | C28: =B28*(1+Assumptions!$C$46) | D28: =C28*(1+Assumptions!$C$46) | E28: =D28*(1+Assumptions!$C$46)
A29: Total Shareholders' Equity | B29: =Historicals!D50 | C29: =B29+'Margin Bridge'!C20-C28 | D29: =C29+'Margin Bridge'!D20-D28 | E29: =D29+'Margin Bridge'!E20-E28
A30: Total Liabilities & Equity | B30: =B26+B29 | C30: =C26+C29 | D30: =D26+D29 | E30: =E26+E29
A31: Balance Check (should = 0) | B31: =B16-B30 | C31: =C16-C30 | D31: =D16-D30 | E31: =E16-E30

Sheet Cash Flow
A1: Cash Flow Statement — FY2026A-FY2029E
A2: Scenario active: | B2: =Assumptions!C3
A3: $ in millions
A4: Line Item | B4: FY2026A | C4: FY2027E | D4: FY2028E | E4: FY2029E
A5: Net Income | B5: ='Margin Bridge'!B20 | C5: ='Margin Bridge'!C20 | D5: ='Margin Bridge'!D20 | E5: ='Margin Bridge'!E20
A6: (+) Depreciation | B6: n/a | C6: ='Balance Sheet'!C12 | D6: ='Balance Sheet'!D12 | E6: ='Balance Sheet'!E12
A7: (-) Increase in Accounts Receivable | B7: n/a | C7: =-('Balance Sheet'!C7-'Balance Sheet'!B7) | D7: =-('Balance Sheet'!D7-'Balance Sheet'!C7) | E7: =-('Balance Sheet'!E7-'Balance Sheet'!D7)
A8: (-) Increase in Inventory | B8: n/a | C8: =-('Balance Sheet'!C8-'Balance Sheet'!B8) | D8: =-('Balance Sheet'!D8-'Balance Sheet'!C8) | E8: =-('Balance Sheet'!E8-'Balance Sheet'!D8)
A9: (+) Increase in Accounts Payable | B9: n/a | C9: ='Balance Sheet'!C18-'Balance Sheet'!B18 | D9: ='Balance Sheet'!D18-'Balance Sheet'!C18 | E9: ='Balance Sheet'!E18-'Balance Sheet'!D18
A10: Cash from Operating Activities | B10: =Historicals!D57 | C10: =SUM(C5:C9) | D10: =SUM(D5:D9) | E10: =SUM(E5:E9)
A12: Capital Expenditures | B12: =Historicals!D58 | C12: =-'Balance Sheet'!C11 | D12: =-'Balance Sheet'!D11 | E12: =-'Balance Sheet'!E11
A13: Cash from Investing Activities | B13: =B12 | C13: =C12 | D13: =D12 | E13: =E12
A15: Dividends Paid | B15: =Historicals!D60 | C15: =-'Balance Sheet'!C28 | D15: =-'Balance Sheet'!D28 | E15: =-'Balance Sheet'!E28
A16: Cash from Financing Activities | B16: =B15 | C16: =C15 | D16: =D15 | E16: =E15
A18: Net Change in Cash | B18: =B10+B13+B16 | C18: =C10+C13+C16 | D18: =D10+D13+D16 | E18: =E10+E13+E16
A20: Note: FY2026A column shows actual reported cash flow summary for reference. Working-capital-driven detail (rows 6-9) is not available for FY2026A since it requires a prior-year balance sheet not built in this model; the projected years (FY2027E-FY2029E) are fully computed.

Sheet Scenario Dashboard
A1: Scenario Comparison — FY2029E Outcomes
A2: $ in millions, except per-share data and percentages
A3: Segment Revenue by Scenario, FY2029E
A4: Segment | B4: Bull | C4: Base | D4: Bear
A5: North America | B5: =Historicals!$D$5*(1+SUMIFS(Assumptions!$C$6:$C$17,Assumptions!$A$6:$A$17,$A5,Assumptions!$B$6:$B$17,"Bull"))*(1+SUMIFS(Assumptions!$D$6:$D$17,Assumptions!$A$6:$A$17,$A5,Assumptions!$B$6:$B$17,"Bull"))*(1+SUMIFS(Assumptions!$E$6:$E$17,Assumptions!$A$6:$A$17,$A5,Assumptions!$B$6:$B$17,"Bull")) | C5: =Historicals!$D$5*(1+SUMIFS(Assumptions!$C$6:$C$17,Assumptions!$A$6:$A$17,$A5,Assumptions!$B$6:$B$17,"Base"))*(1+SUMIFS(Assumptions!$D$6:$D$17,Assumptions!$A$6:$A$17,$A5,Assumptions!$B$6:$B$17,"Base"))*(1+SUMIFS(Assumptions!$E$6:$E$17,Assumptions!$A$6:$A$17,$A5,Assumptions!$B$6:$B$17,"Base")) | D5: =Historicals!$D$5*(1+SUMIFS(Assumptions!$C$6:$C$17,Assumptions!$A$6:$A$17,$A5,Assumptions!$B$6:$B$17,"Bear"))*(1+SUMIFS(Assumptions!$D$6:$D$17,Assumptions!$A$6:$A$17,$A5,Assumptions!$B$6:$B$17,"Bear"))*(1+SUMIFS(Assumptions!$E$6:$E$17,Assumptions!$A$6:$A$17,$A5,Assumptions!$B$6:$B$17,"Bear"))
A6: EMEA | B6: =Historicals!$D$6*(1+SUMIFS(Assumptions!$C$6:$C$17,Assumptions!$A$6:$A$17,$A6,Assumptions!$B$6:$B$17,"Bull"))*(1+SUMIFS(Assumptions!$D$6:$D$17,Assumptions!$A$6:$A$17,$A6,Assumptions!$B$6:$B$17,"Bull"))*(1+SUMIFS(Assumptions!$E$6:$E$17,Assumptions!$A$6:$A$17,$A6,Assumptions!$B$6:$B$17,"Bull")) | C6: =Historicals!$D$6*(1+SUMIFS(Assumptions!$C$6:$C$17,Assumptions!$A$6:$A$17,$A6,Assumptions!$B$6:$B$17,"Base"))*(1+SUMIFS(Assumptions!$D$6:$D$17,Assumptions!$A$6:$A$17,$A6,Assumptions!$B$6:$B$17,"Base"))*(1+SUMIFS(Assumptions!$E$6:$E$17,Assumptions!$A$6:$A$17,$A6,Assumptions!$B$6:$B$17,"Base")) | D6: =Historicals!$D$6*(1+SUMIFS(Assumptions!$C$6:$C$17,Assumptions!$A$6:$A$17,$A6,Assumptions!$B$6:$B$17,"Bear"))*(1+SUMIFS(Assumptions!$D$6:$D$17,Assumptions!$A$6:$A$17,$A6,Assumptions!$B$6:$B$17,"Bear"))*(1+SUMIFS(Assumptions!$E$6:$E$17,Assumptions!$A$6:$A$17,$A6,Assumptions!$B$6:$B$17,"Bear"))
A7: Greater China | B7: =Historicals!$D$7*(1+SUMIFS(Assumptions!$C$6:$C$17,Assumptions!$A$6:$A$17,$A7,Assumptions!$B$6:$B$17,"Bull"))*(1+SUMIFS(Assumptions!$D$6:$D$17,Assumptions!$A$6:$A$17,$A7,Assumptions!$B$6:$B$17,"Bull"))*(1+SUMIFS(Assumptions!$E$6:$E$17,Assumptions!$A$6:$A$17,$A7,Assumptions!$B$6:$B$17,"Bull")) | C7: =Historicals!$D$7*(1+SUMIFS(Assumptions!$C$6:$C$17,Assumptions!$A$6:$A$17,$A7,Assumptions!$B$6:$B$17,"Base"))*(1+SUMIFS(Assumptions!$D$6:$D$17,Assumptions!$A$6:$A$17,$A7,Assumptions!$B$6:$B$17,"Base"))*(1+SUMIFS(Assumptions!$E$6:$E$17,Assumptions!$A$6:$A$17,$A7,Assumptions!$B$6:$B$17,"Base")) | D7: =Historicals!$D$7*(1+SUMIFS(Assumptions!$C$6:$C$17,Assumptions!$A$6:$A$17,$A7,Assumptions!$B$6:$B$17,"Bear"))*(1+SUMIFS(Assumptions!$D$6:$D$17,Assumptions!$A$6:$A$17,$A7,Assumptions!$B$6:$B$17,"Bear"))*(1+SUMIFS(Assumptions!$E$6:$E$17,Assumptions!$A$6:$A$17,$A7,Assumptions!$B$6:$B$17,"Bear"))
A8: APLA | B8: =Historicals!$D$8*(1+SUMIFS(Assumptions!$C$6:$C$17,Assumptions!$A$6:$A$17,$A8,Assumptions!$B$6:$B$17,"Bull"))*(1+SUMIFS(Assumptions!$D$6:$D$17,Assumptions!$A$6:$A$17,$A8,Assumptions!$B$6:$B$17,"Bull"))*(1+SUMIFS(Assumptions!$E$6:$E$17,Assumptions!$A$6:$A$17,$A8,Assumptions!$B$6:$B$17,"Bull")) | C8: =Historicals!$D$8*(1+SUMIFS(Assumptions!$C$6:$C$17,Assumptions!$A$6:$A$17,$A8,Assumptions!$B$6:$B$17,"Base"))*(1+SUMIFS(Assumptions!$D$6:$D$17,Assumptions!$A$6:$A$17,$A8,Assumptions!$B$6:$B$17,"Base"))*(1+SUMIFS(Assumptions!$E$6:$E$17,Assumptions!$A$6:$A$17,$A8,Assumptions!$B$6:$B$17,"Base")) | D8: =Historicals!$D$8*(1+SUMIFS(Assumptions!$C$6:$C$17,Assumptions!$A$6:$A$17,$A8,Assumptions!$B$6:$B$17,"Bear"))*(1+SUMIFS(Assumptions!$D$6:$D$17,Assumptions!$A$6:$A$17,$A8,Assumptions!$B$6:$B$17,"Bear"))*(1+SUMIFS(Assumptions!$E$6:$E$17,Assumptions!$A$6:$A$17,$A8,Assumptions!$B$6:$B$17,"Bear"))
A9: Converse | B9: =Historicals!$D$9*(1+Assumptions!$C$50)*(1+Assumptions!$D$50)*(1+Assumptions!$E$50) | C9: =Historicals!$D$9*(1+Assumptions!$C$50)*(1+Assumptions!$D$50)*(1+Assumptions!$E$50) | D9: =Historicals!$D$9*(1+Assumptions!$C$50)*(1+Assumptions!$D$50)*(1+Assumptions!$E$50)
A10: Other (Global Brand Div. & Corporate) | B10: =Historicals!$D$10 | C10: =Historicals!$D$10 | D10: =Historicals!$D$10
A11: Total Consolidated Revenue, FY2029E | B11: =SUM(B5:B10) | C11: =SUM(C5:C10) | D11: =SUM(D5:D10)
A13: Profitability by Scenario, FY2029E
A14: Metric | B14: Bull | C14: Base | D14: Bear
A15: Gross Margin % | B15: =SUMIFS(Assumptions!$E$25:$E$39,Assumptions!$A$25:$A$39,"Gross Margin %",Assumptions!$B$25:$B$39,"Bull") | C15: =SUMIFS(Assumptions!$E$25:$E$39,Assumptions!$A$25:$A$39,"Gross Margin %",Assumptions!$B$25:$B$39,"Base") | D15: =SUMIFS(Assumptions!$E$25:$E$39,Assumptions!$A$25:$A$39,"Gross Margin %",Assumptions!$B$25:$B$39,"Bear")
A16: SG&A % of Revenue | B16: =SUMIFS(Assumptions!$E$25:$E$39,Assumptions!$A$25:$A$39,"SG&A % of Revenue",Assumptions!$B$25:$B$39,"Bull") | C16: =SUMIFS(Assumptions!$E$25:$E$39,Assumptions!$A$25:$A$39,"SG&A % of Revenue",Assumptions!$B$25:$B$39,"Base") | D16: =SUMIFS(Assumptions!$E$25:$E$39,Assumptions!$A$25:$A$39,"SG&A % of Revenue",Assumptions!$B$25:$B$39,"Bear")
A17: Operating Income | B17: =B11*(B15-B16) | C17: =C11*(C15-C16) | D17: =D11*(D15-D16)
A18: Net Income (after interest & tax) | B18: =(B17-'Margin Bridge'!$E$17)*(1-Assumptions!$C$41) | C18: =(C17-'Margin Bridge'!$E$17)*(1-Assumptions!$C$41) | D18: =(D17-'Margin Bridge'!$E$17)*(1-Assumptions!$C$41)
A19: Diluted EPS | B19: =B18/Assumptions!$C$48 | C19: =C18/Assumptions!$C$48 | D19: =D18/Assumptions!$C$48
A22: Consensus Sanity Check — Diluted EPS, FY2027E-FY2029E
A23: Source | B23: FY2027E | C23: FY2028E | D23: FY2029E | E23: Note
A24: This model (Base case) | B24: ='Margin Bridge'!C22 | C24: ='Margin Bridge'!D22 | D24: ='Margin Bridge'!E22 | E24: Computed from full linked, consolidated-scope model
A25: Zacks Research consensus | B25: 1.69 | C25: 2.11 | D25: 2.63 | E25: Directly published, dated July 21, 2026 (themarketsdaily.com / Zacks Research)
A26: JPMorgan (bearish case) | B26: 1.55 | C26: 1.72 | D26: n/a | E26: Downgraded to Underweight July 2026; did not publish an FY2029E estimate
A27: This model vs. Zacks consensus | B27: =B24/B25-1 | C27: =C24/C25-1 | D27: =D24/D25-1
A29: Note: figures above reflect the corrected consolidated revenue scope (NIKE Brand geographic segments plus Converse and Corporate/GBD), matching the Balance Sheet's consolidated basis. This model's FY2027E EPS runs modestly above Zacks consensus; FY2028E and FY2029E run modestly below, consistent with this model's more conservative Greater China recovery assumption. All three years remain well above JPMorgan's bearish case.
A32: Breakeven Analysis: Does North America Offset Greater China by FY2028E? (Base Case)
A33: Metric | B33: Value | C33: Note
A34: Greater China Revenue, FY2026A | B34: ='Segment Revenue Build'!B7
A35: Greater China Revenue, FY2028E (Base) | B35: ='Segment Revenue Build'!D7
A36: Greater China Dollar Decline, FY26A-FY28E | B36: =B34-B35
A37: North America Revenue, FY2026A | B37: ='Segment Revenue Build'!B5
A38: North America Revenue Required by FY2028E to Fully Offset | B38: =B37+B36
A39: Required North America Annualized Growth (FY26A-FY28E) | B39: =(B38/B37)^(1/2)-1
A40: North America Revenue, FY2028E (Base Case Actual) | B40: ='Segment Revenue Build'!D5
A41: Base Case North America Annualized Growth (FY26A-FY28E) | B41: =(B40/B37)^(1/2)-1
A42: Cushion: Actual FY2028E NA Revenue vs. Required | B42: =B40-B38 | C42: Answers the thesis question directly: the offset holds, with this dollar cushion
