Workbook

Sheet Read Me
A1: Microsoft / Activision Blizzard — M&A Accretion/Dilution & Strategic Analysis
A3: Thesis question:
A4: Was Microsoft's acquisition of Activision Blizzard financially justified, and what level of annual synergies was required for the deal to become EPS accretive?
A6: Build phases:
A7: • Phase 1: Transaction terms, purchase price allocation, standalone historicals — COMPLETE
A8: • Phase 2: Sources & uses, financing structure — COMPLETE
A9: • Phase 3: Accretion/dilution EPS bridge — COMPLETE
A10: • Phase 4: Synergy breakeven sensitivity — COMPLETE / PUBLISHABLE CHECKPOINT
A11: • Phase 5: Combined pro forma income statement — IN PROGRESS (starter earnings bridge built)
A12: • Phase 6: Combined pro forma balance sheet
A13: • Phase 7: Combined cash flow + debt paydown
A14: • Phase 8: Strategic analysis, report, and deck
A16: Color legend:
A17: Blue text | B17: Hardcoded input, sourced from filings
A18: Black text | B18: Formula
A19: Green text | B19: Cross-sheet link
A21: Note: standalone historicals use each company's last full pre-close reporting year — Microsoft's FY2023 (ended June 30, 2023) and Activision's FY2022 (calendar year) — since the deal closed October 13, 2023, partway through Microsoft's FY2024.

Sheet Transaction Terms
A1: Transaction Terms
A3: Item | B3: Value | C3: Source
A4: Announcement date | B4: January 18, 2022 | C4: Microsoft/Activision joint press release
A5: Close date | B5: October 13, 2023 | C5: Microsoft FY2024 10-K
A6: Price per share (all-cash) | B6: 95 | C6: Deal agreement; Microsoft FY2024 10-K
A7: Activision unaffected share price (Jan 14, 2022 close) | B7: 65.39 | C7: Market data, last trading day before announcement
A8: Premium to unaffected price | B8: =B6/B7-1 -> 0.45282153
A10: Headline vs. Accounting Purchase Price
A11: Measure | B11: Amount ($mm) | C11: How it's used
A12: Announced headline deal value | B12: 68700 | C12: Deal overview / media framing
A13: Final purchase-accounting price | B13: 75408 | C13: Microsoft final purchase price allocation (FY2025 10-K; $75.408B)
A14: Cash acquired from Activision | B14: 12976 | C14: Balance sheet / net cash consideration
A15: Cash paid, net of cash acquired | B15: 61800 | C15: Financing / cash flow analysis
A16: Activision long-term debt assumed | B16: 2799 | C16: Pro forma debt / EV considerations
A17: Source: Microsoft FY2024 Form 10-K (business combination note)

Sheet Purchase Price Allocation
A1: Purchase Price Allocation
A3: Item | B3: Amount ($mm) | C3: Note
A4: Total purchase price | B4: 75408 | C4: Final consideration transferred
A5: Cash and cash equivalents acquired | B5: 12976 | C5: Part of net assets acquired
A6: Goodwill | B6: 51001 | C6: Final goodwill allocation; primarily attributed to expected integration synergies
A7: Identifiable intangible assets | B7: 21969 | C7: Final identifiable intangibles: marketing, technology, customer-related
A8: Long-term debt assumed | B8: 2799 | C8: Activision's existing notes, later mostly exchanged for MSFT notes
A10: Note: final purchase price allocation per Microsoft's FY2025 10-K. Intangible detail: $11,619mm marketing-related (24 yrs), $9,689mm technology-based (4 yrs), $661mm customer-related (4 yrs).

Sheet Microsoft Standalone
A1: Microsoft, Inc. — Standalone Historicals (Pre-Acquisition)
A2: $ in millions except per-share data. FY ended June 30. FY2023 is the last full year before the October 2023 close.
A4: Metric | B4: FY2023A | C4: Source
A5: Revenue | B5: 211915 | C5: Microsoft FY2023 Form 10-K / FY23 Q4 press release
A6: Operating Income | B6: 88523 | C6: Microsoft FY2023 Form 10-K / FY23 Q4 press release
A7: Net Income | B7: 72361 | C7: Microsoft FY2023 Form 10-K / FY23 Q4 press release
A8: Diluted EPS ($) | B8: 9.68 | C8: Microsoft FY2023 Form 10-K / FY23 Q4 press release
A9: Diluted Shares Outstanding (mm) | B9: 7472 | C9: Microsoft FY2023 Form 10-K, reported diluted weighted-average shares
A10: Operating Margin | B10: =B6/B5 -> 0.41772881
A11: Derived diluted shares check (Net Income / EPS) | B11: =B7/B8 -> 7475.3099 | C11: Check only

Sheet Activision Standalone
A1: Activision Blizzard, Inc. — Standalone Historicals (Pre-Acquisition)
A2: $ in millions except per-share data. FY is calendar year. FY2022 is the last full year before the October 2023 close.
A4: Metric | B4: FY2022A | C4: Source
A5: Revenue | B5: 7528 | C5: Activision Blizzard FY2022 Form 10-K, consolidated statement of operations
A6: Net Income | B6: 1513 | C6: Activision Blizzard FY2022 Form 10-K / FY2022 earnings release
A7: Diluted EPS ($) | B7: 1.92 | C7: Activision Blizzard FY2022 Form 10-K (10-K figure; differs from earnings-release rounding of $1.94)
A8: GAAP Operating Margin | B8: =B9/B5 -> 0.22183847 | C8: Calculated from exact reported operating income / revenue
A9: Operating Income | B9: 1670 | C9: Activision Blizzard FY2022 Form 10-K / FY2022 earnings release
A10: Diluted Shares Outstanding (mm) | B10: 789 | C10: Activision Blizzard FY2022 Form 10-K, reported diluted weighted-average shares
A11: Derived diluted shares check (Net Income / EPS) | B11: =B6/B7 -> 788.02083 | C11: Check only
A13: Pretax Income (exact, reported) | B13: 1744 | C13: Activision Blizzard FY2022 10-K / Q4 2022 earnings release exhibit, consolidated statement of operations
A14: Income Tax Expense (exact, reported) | B14: 231 | C14: Activision Blizzard FY2022 10-K, consolidated statement of operations
A15: Implied Effective Tax Rate | B15: =B14/B13 -> 0.13245413 | C15: Tax Expense / Pretax Income; used as the Year-1 starting rate in the Phase 5 tax transition

Sheet Sources & Uses
A1: Phase 2 — Sources & Uses
A2: Actual deal mechanics: primarily cash-funded; model focuses on cash opportunity cost rather than invented acquisition debt.
A4: Transaction Funding Bridge
A5: Item | B5: Amount ($mm) | C5: Type | D5: Source / Note
A6: Cash paid, net of cash acquired | B6: ='Transaction Terms'!B15 -> 61800 | C6: Use | D6: Microsoft FY2024 10-K / Oct. 2023 10-Q
A7: Cash acquired from Activision | B7: ='Transaction Terms'!B14 -> 12976 | C7: Acquired cash | D7: Microsoft FY2024 10-K PPA
A8: Gross cash consideration | B8: =SUM(B6:B7) -> 74776 | C8: Derived | D8: Net cash paid + acquired cash
A9: Purchase-accounting price | B9: ='Transaction Terms'!B13 -> 75408 | C9: Accounting value | D9: Microsoft FY2024 10-K PPA
A10: Difference vs. gross cash consideration | B10: =B9-B8 -> 632 | C10: Derived | D10: Purchase-accounting / consideration difference; not assumed to be new debt
A11: Long-term debt assumed | B11: ='Transaction Terms'!B16 -> 2799 | C11: Assumed liability | D11: Activision debt assumed; not acquisition-specific new financing
A13: Accretion / Dilution Financing Assumptions
A14: Assumption | B14: Value | C14: Treatment | D14: Source / Rationale
A15: Net cash deployed ($mm) | B15: =B6 -> 61800 | C15: Foregone interest income | D15: Linked to reported net cash payment
A16: Foregone cash yield | B16: 0.04 | C16: Scenario input | D16: Illustrative base case; sensitivity tested in Phase 4
A17: Microsoft effective tax rate | B17: =16950/89311 -> 0.18978625 | C17: Tax-effects financing & amortization | D17: FY2023 provision / pretax income
A18: New acquisition debt issued | B18: 0 | C18: No incremental interest expense | D18: No acquisition-specific debt issuance assumed
A19: New shares issued for consideration | B19: 0 | C19: No dilution from consideration | D19: $95/share all-cash transaction
A21: Opportunity Cost of Cash
A22: Calculation | B22: Amount ($mm) | C22: Formula Logic | D22: Comment
A23: Foregone pre-tax interest income | B23: =B15*B16 -> 2472 | C23: Net cash deployed × foregone yield | D23: Primary financing cost in the model
A24: Tax shield / tax effect | B24: =B23*B17 -> 469.15162 | C24: Foregone interest × tax rate | D24: Reduces after-tax EPS impact
A25: Foregone after-tax interest income | B25: =B23-B24 -> 2002.8484 | C25: Pre-tax interest × (1 − tax rate) | D25: Flows into Phase 3 EPS bridge
A27: Primary sources: https://www.sec.gov/Archives/edgar/data/789019/000095017024087843/msft-20240630.htm | https://www.sec.gov/Archives/edgar/data/789019/000095017023054855/msft-20230930.htm

Sheet Accretion Dilution
A1: Phase 3 — Accretion / Dilution
A2: Pre-close standalone earnings plus transaction adjustments. No synergies are assumed in the base case; Phase 4 solves for breakeven.
A4: Purchase Accounting Amortization
A5: Acquired Intangible | B5: Fair Value ($mm) | C5: Weighted Avg. Life | D5: Annual Amortization ($mm)
A6: Marketing-related | B6: 11619 | C6: 24 | D6: =B6/C6 -> 484.125
A7: Technology-based | B7: 9689 | C7: 4 | D7: =B7/C7 -> 2422.25
A8: Customer-related | B8: 661 | C8: 4 | D8: =B8/C8 -> 165.25
A9: Total / blended | B9: =SUM(B6:B8) -> 21969 | D9: =SUM(D6:D8) -> 3071.625
A11: EPS Bridge — No Synergies Base Case
A12: Item | B12: Amount ($mm) | C12: Per Share / % | D12: Source / Logic
A13: Microsoft standalone net income | B13: ='Microsoft Standalone'!B7 -> 72361 | D13: FY2023A
A14: + Activision standalone net income | B14: ='Activision Standalone'!B6 -> 1513 | D14: FY2022A
A15: - Foregone after-tax interest income | B15: ='Sources & Uses'!B25 -> 2002.8484 | D15: Phase 2
A16: - After-tax purchase accounting amortization | B16: =D9*(1-'Sources & Uses'!B17) -> 2488.6728 | D16: Annual amortization × (1 − tax rate)
A17: + After-tax synergies | B17: 0 | D17: Base case assumes $0
A18: Pro forma net income | B18: =B13+B14-B15-B16+B17 -> 69382.479 | D18: Sum of above
A19: Microsoft diluted shares (mm) | B19: ='Microsoft Standalone'!B9 -> 7472 | D19: Reported FY2023 diluted weighted-average shares
A20: Pro forma diluted EPS | B20: =B18/B19 -> 9.2856637 | D20: Pro forma NI / diluted shares
A21: Microsoft standalone diluted EPS | B21: ='Microsoft Standalone'!B8 -> 9.68 | D21: Reported FY2023 EPS
A22: EPS accretion / (dilution) | B22: =B20/B21-1 -> -0.040737226 | D22: Pro forma EPS / standalone EPS − 1
A24: Independent Check Against Microsoft's Reported Pro Forma Disclosure
A25: Metric | B25: Microsoft Reported Pro Forma FY2023 | C25: Our Base Case | D25: Comment
A26: Net Income ($mm) | B26: 71383 | C26: =B18 -> 69382.479 | D26: Microsoft's unaudited pro forma assumes acquisition occurred July 1, 2022; useful benchmark, not expected to match our simplified pre-close bridge exactly.
A27: Diluted EPS ($) | B27: 9.55 | C27: =B20 -> 9.2856637 | D27: Reported pro forma from business-combination footnote
A28: Difference in EPS | C28: =C27-B27 -> -0.26433635 | D28: Our model vs. Microsoft reported pro forma
A30: Source: https://www.sec.gov/Archives/edgar/data/789019/000095017025100235/R35.htm

Sheet Synergy Breakeven
A1: Phase 4 — Synergy Breakeven
A2: Core question: how much annual pre-tax run-rate synergy is required for the transaction to become EPS-neutral under different opportunity costs of cash?
A4: Base-Case Breakeven
A5: Input / Output | B5: Value | C5: Units | D5: Logic
A6: Activision standalone net income | B6: ='Activision Standalone'!B6 -> 1513 | C6: $mm | D6: Standalone earnings contribution
A7: Annual purchase-accounting amortization | B7: ='Accretion Dilution'!D9 -> 3071.625 | C7: $mm | D7: From acquired intangible lives
A8: Foregone cash yield | B8: ='Sources & Uses'!B16 -> 0.04 | D8: Phase 2 base assumption
A9: Microsoft effective tax rate | B9: ='Sources & Uses'!B17 -> 0.18978625 | D9: FY2023A
A10: Required annual pre-tax synergies | B10: =((('Microsoft Standalone'!B8*'Microsoft Standalone'!B9)-'Microsoft Standalone'!B7-'Activision Standalone'!B6+('Sources & Uses'!B15*B8*(1-'Sources & Uses'!B17))+('Accretion Dilution'!D9*(1-'Sources & Uses'!B17)))/(1-'Sources & Uses'!B17)) -> 3636.6714 | C10: $mm | D10: Solves to EPS-neutral
A11: Required synergies / Activision FY2022 revenue | B11: =B10/'Activision Standalone'!B5 -> 0.483086 | D11: Scale check
A13: Breakeven Synergies by Foregone Cash Yield
A14: Cash Yield | B14: 0.02 | C14: 0.03 | D14: 0.04 | E14: 0.05 | F14: 0.06
A15: Required Synergies ($mm) | B15: =((('Microsoft Standalone'!B8*'Microsoft Standalone'!B9)-'Microsoft Standalone'!B7-'Activision Standalone'!B6+('Sources & Uses'!B15*B14*(1-'Sources & Uses'!B17))+('Accretion Dilution'!D9*(1-'Sources & Uses'!B17)))/(1-'Sources & Uses'!B17)) -> 2400.6714 | C15: =((('Microsoft Standalone'!B8*'Microsoft Standalone'!B9)-'Microsoft Standalone'!B7-'Activision Standalone'!B6+('Sources & Uses'!B15*C14*(1-'Sources & Uses'!B17))+('Accretion Dilution'!D9*(1-'Sources & Uses'!B17)))/(1-'Sources & Uses'!B17)) -> 3018.6714 | D15: =((('Microsoft Standalone'!B8*'Microsoft Standalone'!B9)-'Microsoft Standalone'!B7-'Activision Standalone'!B6+('Sources & Uses'!B15*D14*(1-'Sources & Uses'!B17))+('Accretion Dilution'!D9*(1-'Sources & Uses'!B17)))/(1-'Sources & Uses'!B17)) -> 3636.6714 | E15: =((('Microsoft Standalone'!B8*'Microsoft Standalone'!B9)-'Microsoft Standalone'!B7-'Activision Standalone'!B6+('Sources & Uses'!B15*E14*(1-'Sources & Uses'!B17))+('Accretion Dilution'!D9*(1-'Sources & Uses'!B17)))/(1-'Sources & Uses'!B17)) -> 4254.6714 | F15: =((('Microsoft Standalone'!B8*'Microsoft Standalone'!B9)-'Microsoft Standalone'!B7-'Activision Standalone'!B6+('Sources & Uses'!B15*F14*(1-'Sources & Uses'!B17))+('Accretion Dilution'!D9*(1-'Sources & Uses'!B17)))/(1-'Sources & Uses'!B17)) -> 4872.6714
A18: EPS Sensitivity — Synergies vs. Cash Yield
A19: Annual Synergies ($mm) | B19: 0.02 | C19: 0.03 | D19: 0.04 | E19: 0.05 | F19: 0.06
A20: 0 | B20: =(('Microsoft Standalone'!B7+'Activision Standalone'!B6-('Sources & Uses'!B15*B$19*(1-'Sources & Uses'!B17))-('Accretion Dilution'!D9*(1-'Sources & Uses'!B17))+($A20*(1-'Sources & Uses'!B17)))/'Microsoft Standalone'!B9/'Microsoft Standalone'!B8)-1 -> -0.026891815 | C20: =(('Microsoft Standalone'!B7+'Activision Standalone'!B6-('Sources & Uses'!B15*C$19*(1-'Sources & Uses'!B17))-('Accretion Dilution'!D9*(1-'Sources & Uses'!B17))+($A20*(1-'Sources & Uses'!B17)))/'Microsoft Standalone'!B9/'Microsoft Standalone'!B8)-1 -> -0.03381452 | D20: =(('Microsoft Standalone'!B7+'Activision Standalone'!B6-('Sources & Uses'!B15*D$19*(1-'Sources & Uses'!B17))-('Accretion Dilution'!D9*(1-'Sources & Uses'!B17))+($A20*(1-'Sources & Uses'!B17)))/'Microsoft Standalone'!B9/'Microsoft Standalone'!B8)-1 -> -0.040737226 | E20: =(('Microsoft Standalone'!B7+'Activision Standalone'!B6-('Sources & Uses'!B15*E$19*(1-'Sources & Uses'!B17))-('Accretion Dilution'!D9*(1-'Sources & Uses'!B17))+($A20*(1-'Sources & Uses'!B17)))/'Microsoft Standalone'!B9/'Microsoft Standalone'!B8)-1 -> -0.047659932 | F20: =(('Microsoft Standalone'!B7+'Activision Standalone'!B6-('Sources & Uses'!B15*F$19*(1-'Sources & Uses'!B17))-('Accretion Dilution'!D9*(1-'Sources & Uses'!B17))+($A20*(1-'Sources & Uses'!B17)))/'Microsoft Standalone'!B9/'Microsoft Standalone'!B8)-1 -> -0.054582637
A21: 1000 | B21: =(('Microsoft Standalone'!B7+'Activision Standalone'!B6-('Sources & Uses'!B15*B$19*(1-'Sources & Uses'!B17))-('Accretion Dilution'!D9*(1-'Sources & Uses'!B17))+($A21*(1-'Sources & Uses'!B17)))/'Microsoft Standalone'!B9/'Microsoft Standalone'!B8)-1 -> -0.015690026 | C21: =(('Microsoft Standalone'!B7+'Activision Standalone'!B6-('Sources & Uses'!B15*C$19*(1-'Sources & Uses'!B17))-('Accretion Dilution'!D9*(1-'Sources & Uses'!B17))+($A21*(1-'Sources & Uses'!B17)))/'Microsoft Standalone'!B9/'Microsoft Standalone'!B8)-1 -> -0.022612731 | D21: =(('Microsoft Standalone'!B7+'Activision Standalone'!B6-('Sources & Uses'!B15*D$19*(1-'Sources & Uses'!B17))-('Accretion Dilution'!D9*(1-'Sources & Uses'!B17))+($A21*(1-'Sources & Uses'!B17)))/'Microsoft Standalone'!B9/'Microsoft Standalone'!B8)-1 -> -0.029535437 | E21: =(('Microsoft Standalone'!B7+'Activision Standalone'!B6-('Sources & Uses'!B15*E$19*(1-'Sources & Uses'!B17))-('Accretion Dilution'!D9*(1-'Sources & Uses'!B17))+($A21*(1-'Sources & Uses'!B17)))/'Microsoft Standalone'!B9/'Microsoft Standalone'!B8)-1 -> -0.036458143 | F21: =(('Microsoft Standalone'!B7+'Activision Standalone'!B6-('Sources & Uses'!B15*F$19*(1-'Sources & Uses'!B17))-('Accretion Dilution'!D9*(1-'Sources & Uses'!B17))+($A21*(1-'Sources & Uses'!B17)))/'Microsoft Standalone'!B9/'Microsoft Standalone'!B8)-1 -> -0.043380848
A22: 2000 | B22: =(('Microsoft Standalone'!B7+'Activision Standalone'!B6-('Sources & Uses'!B15*B$19*(1-'Sources & Uses'!B17))-('Accretion Dilution'!D9*(1-'Sources & Uses'!B17))+($A22*(1-'Sources & Uses'!B17)))/'Microsoft Standalone'!B9/'Microsoft Standalone'!B8)-1 -> -0.0044882368 | C22: =(('Microsoft Standalone'!B7+'Activision Standalone'!B6-('Sources & Uses'!B15*C$19*(1-'Sources & Uses'!B17))-('Accretion Dilution'!D9*(1-'Sources & Uses'!B17))+($A22*(1-'Sources & Uses'!B17)))/'Microsoft Standalone'!B9/'Microsoft Standalone'!B8)-1 -> -0.011410942 | D22: =(('Microsoft Standalone'!B7+'Activision Standalone'!B6-('Sources & Uses'!B15*D$19*(1-'Sources & Uses'!B17))-('Accretion Dilution'!D9*(1-'Sources & Uses'!B17))+($A22*(1-'Sources & Uses'!B17)))/'Microsoft Standalone'!B9/'Microsoft Standalone'!B8)-1 -> -0.018333648 | E22: =(('Microsoft Standalone'!B7+'Activision Standalone'!B6-('Sources & Uses'!B15*E$19*(1-'Sources & Uses'!B17))-('Accretion Dilution'!D9*(1-'Sources & Uses'!B17))+($A22*(1-'Sources & Uses'!B17)))/'Microsoft Standalone'!B9/'Microsoft Standalone'!B8)-1 -> -0.025256354 | F22: =(('Microsoft Standalone'!B7+'Activision Standalone'!B6-('Sources & Uses'!B15*F$19*(1-'Sources & Uses'!B17))-('Accretion Dilution'!D9*(1-'Sources & Uses'!B17))+($A22*(1-'Sources & Uses'!B17)))/'Microsoft Standalone'!B9/'Microsoft Standalone'!B8)-1 -> -0.032179059
A23: 3000 | B23: =(('Microsoft Standalone'!B7+'Activision Standalone'!B6-('Sources & Uses'!B15*B$19*(1-'Sources & Uses'!B17))-('Accretion Dilution'!D9*(1-'Sources & Uses'!B17))+($A23*(1-'Sources & Uses'!B17)))/'Microsoft Standalone'!B9/'Microsoft Standalone'!B8)-1 -> 0.0067135522 | C23: =(('Microsoft Standalone'!B7+'Activision Standalone'!B6-('Sources & Uses'!B15*C$19*(1-'Sources & Uses'!B17))-('Accretion Dilution'!D9*(1-'Sources & Uses'!B17))+($A23*(1-'Sources & Uses'!B17)))/'Microsoft Standalone'!B9/'Microsoft Standalone'!B8)-1 -> -0.00020915339 | D23: =(('Microsoft Standalone'!B7+'Activision Standalone'!B6-('Sources & Uses'!B15*D$19*(1-'Sources & Uses'!B17))-('Accretion Dilution'!D9*(1-'Sources & Uses'!B17))+($A23*(1-'Sources & Uses'!B17)))/'Microsoft Standalone'!B9/'Microsoft Standalone'!B8)-1 -> -0.007131859 | E23: =(('Microsoft Standalone'!B7+'Activision Standalone'!B6-('Sources & Uses'!B15*E$19*(1-'Sources & Uses'!B17))-('Accretion Dilution'!D9*(1-'Sources & Uses'!B17))+($A23*(1-'Sources & Uses'!B17)))/'Microsoft Standalone'!B9/'Microsoft Standalone'!B8)-1 -> -0.014054565 | F23: =(('Microsoft Standalone'!B7+'Activision Standalone'!B6-('Sources & Uses'!B15*F$19*(1-'Sources & Uses'!B17))-('Accretion Dilution'!D9*(1-'Sources & Uses'!B17))+($A23*(1-'Sources & Uses'!B17)))/'Microsoft Standalone'!B9/'Microsoft Standalone'!B8)-1 -> -0.02097727
A24: 4000 | B24: =(('Microsoft Standalone'!B7+'Activision Standalone'!B6-('Sources & Uses'!B15*B$19*(1-'Sources & Uses'!B17))-('Accretion Dilution'!D9*(1-'Sources & Uses'!B17))+($A24*(1-'Sources & Uses'!B17)))/'Microsoft Standalone'!B9/'Microsoft Standalone'!B8)-1 -> 0.017915341 | C24: =(('Microsoft Standalone'!B7+'Activision Standalone'!B6-('Sources & Uses'!B15*C$19*(1-'Sources & Uses'!B17))-('Accretion Dilution'!D9*(1-'Sources & Uses'!B17))+($A24*(1-'Sources & Uses'!B17)))/'Microsoft Standalone'!B9/'Microsoft Standalone'!B8)-1 -> 0.010992636 | D24: =(('Microsoft Standalone'!B7+'Activision Standalone'!B6-('Sources & Uses'!B15*D$19*(1-'Sources & Uses'!B17))-('Accretion Dilution'!D9*(1-'Sources & Uses'!B17))+($A24*(1-'Sources & Uses'!B17)))/'Microsoft Standalone'!B9/'Microsoft Standalone'!B8)-1 -> 0.00406993 | E24: =(('Microsoft Standalone'!B7+'Activision Standalone'!B6-('Sources & Uses'!B15*E$19*(1-'Sources & Uses'!B17))-('Accretion Dilution'!D9*(1-'Sources & Uses'!B17))+($A24*(1-'Sources & Uses'!B17)))/'Microsoft Standalone'!B9/'Microsoft Standalone'!B8)-1 -> -0.0028527756 | F24: =(('Microsoft Standalone'!B7+'Activision Standalone'!B6-('Sources & Uses'!B15*F$19*(1-'Sources & Uses'!B17))-('Accretion Dilution'!D9*(1-'Sources & Uses'!B17))+($A24*(1-'Sources & Uses'!B17)))/'Microsoft Standalone'!B9/'Microsoft Standalone'!B8)-1 -> -0.0097754812
A25: 5000 | B25: =(('Microsoft Standalone'!B7+'Activision Standalone'!B6-('Sources & Uses'!B15*B$19*(1-'Sources & Uses'!B17))-('Accretion Dilution'!D9*(1-'Sources & Uses'!B17))+($A25*(1-'Sources & Uses'!B17)))/'Microsoft Standalone'!B9/'Microsoft Standalone'!B8)-1 -> 0.02911713 | C25: =(('Microsoft Standalone'!B7+'Activision Standalone'!B6-('Sources & Uses'!B15*C$19*(1-'Sources & Uses'!B17))-('Accretion Dilution'!D9*(1-'Sources & Uses'!B17))+($A25*(1-'Sources & Uses'!B17)))/'Microsoft Standalone'!B9/'Microsoft Standalone'!B8)-1 -> 0.022194425 | D25: =(('Microsoft Standalone'!B7+'Activision Standalone'!B6-('Sources & Uses'!B15*D$19*(1-'Sources & Uses'!B17))-('Accretion Dilution'!D9*(1-'Sources & Uses'!B17))+($A25*(1-'Sources & Uses'!B17)))/'Microsoft Standalone'!B9/'Microsoft Standalone'!B8)-1 -> 0.015271719 | E25: =(('Microsoft Standalone'!B7+'Activision Standalone'!B6-('Sources & Uses'!B15*E$19*(1-'Sources & Uses'!B17))-('Accretion Dilution'!D9*(1-'Sources & Uses'!B17))+($A25*(1-'Sources & Uses'!B17)))/'Microsoft Standalone'!B9/'Microsoft Standalone'!B8)-1 -> 0.0083490134 | F25: =(('Microsoft Standalone'!B7+'Activision Standalone'!B6-('Sources & Uses'!B15*F$19*(1-'Sources & Uses'!B17))-('Accretion Dilution'!D9*(1-'Sources & Uses'!B17))+($A25*(1-'Sources & Uses'!B17)))/'Microsoft Standalone'!B9/'Microsoft Standalone'!B8)-1 -> 0.0014263078
A26: 6000 | B26: =(('Microsoft Standalone'!B7+'Activision Standalone'!B6-('Sources & Uses'!B15*B$19*(1-'Sources & Uses'!B17))-('Accretion Dilution'!D9*(1-'Sources & Uses'!B17))+($A26*(1-'Sources & Uses'!B17)))/'Microsoft Standalone'!B9/'Microsoft Standalone'!B8)-1 -> 0.040318919 | C26: =(('Microsoft Standalone'!B7+'Activision Standalone'!B6-('Sources & Uses'!B15*C$19*(1-'Sources & Uses'!B17))-('Accretion Dilution'!D9*(1-'Sources & Uses'!B17))+($A26*(1-'Sources & Uses'!B17)))/'Microsoft Standalone'!B9/'Microsoft Standalone'!B8)-1 -> 0.033396214 | D26: =(('Microsoft Standalone'!B7+'Activision Standalone'!B6-('Sources & Uses'!B15*D$19*(1-'Sources & Uses'!B17))-('Accretion Dilution'!D9*(1-'Sources & Uses'!B17))+($A26*(1-'Sources & Uses'!B17)))/'Microsoft Standalone'!B9/'Microsoft Standalone'!B8)-1 -> 0.026473508 | E26: =(('Microsoft Standalone'!B7+'Activision Standalone'!B6-('Sources & Uses'!B15*E$19*(1-'Sources & Uses'!B17))-('Accretion Dilution'!D9*(1-'Sources & Uses'!B17))+($A26*(1-'Sources & Uses'!B17)))/'Microsoft Standalone'!B9/'Microsoft Standalone'!B8)-1 -> 0.019550802 | F26: =(('Microsoft Standalone'!B7+'Activision Standalone'!B6-('Sources & Uses'!B15*F$19*(1-'Sources & Uses'!B17))-('Accretion Dilution'!D9*(1-'Sources & Uses'!B17))+($A26*(1-'Sources & Uses'!B17)))/'Microsoft Standalone'!B9/'Microsoft Standalone'!B8)-1 -> 0.012628097
A28: Base-case result: at a 4.0% foregone cash yield, the deal requires approximately $3.6B of annual pre-tax synergies to reach EPS neutrality. This is a model-derived hurdle, not management guidance.

Sheet Pro Forma Income Statement
A1: Phase 5 — Combined Pro Forma Income Statement (Starter)
A2: Simplified pro forma earnings view using pre-close standalone results and transaction adjustments. Base case assumes no synergies; breakeven case uses the Phase 4 EPS-neutral synergy requirement.
A4: Metric | B4: Microsoft Standalone | C4: Activision Standalone | D4: Transaction Adjustments | E4: Pro Forma — No Synergies | F4: Pro Forma — Breakeven Synergies | G4: Notes
A5: Revenue ($mm) | B5: ='Microsoft Standalone'!B5 -> 211915 | C5: ='Activision Standalone'!B5 -> 7528 | D5: 0 | E5: =SUM(B5:D5) -> 219443 | F5: =E5 -> 219443 | G5: Historical standalone revenue; no revenue synergies assumed.
A6: Operating Income before PPA / Synergies ($mm) | B6: ='Microsoft Standalone'!B6 -> 88523 | C6: ='Activision Standalone'!B9 -> 1670 | D6: 0 | E6: =SUM(B6:D6) -> 90193 | F6: =E6 -> 90193 | G6: Sum of standalone operating income.
A7: Purchase Accounting Amortization ($mm) | B7: 0 | C7: 0 | D7: =-'Accretion Dilution'!D9 -> -3071.625 | E7: =SUM(B7:D7) -> -3071.625 | F7: =E7 -> -3071.625 | G7: Annual amortization of acquired intangibles.
A8: Pre-Tax Synergies ($mm) | B8: 0 | C8: 0 | D8: 0 | E8: 0 | F8: ='Synergy Breakeven'!B10 -> 3636.6714 | G8: Base = $0; breakeven from Phase 4.
A9: Adjusted Operating Income ($mm) | B9: =B6 -> 88523 | C9: =C6 -> 1670 | D9: =D7+D8 -> -3071.625 | E9: =SUM(B9:D9) -> 87121.375 | F9: =B6+C6+D7+F8 -> 90758.046 | G9: Standalone operating income less PPA amortization plus synergies.
A10: Operating Margin | B10: =B9/B5 -> 0.41772881 | C10: =C9/C5 -> 0.22183847 | E10: =E9/E5 -> 0.39701141 | F10: =F9/F5 -> 0.41358369 | G10: Adjusted operating income / combined revenue.
A12: Standalone Net Income Contribution ($mm) | B12: ='Microsoft Standalone'!B7 -> 72361 | C12: ='Activision Standalone'!B6 -> 1513 | D12: 0 | E12: =SUM(B12:D12) -> 73874 | F12: =E12 -> 73874 | G12: Uses each company's reported pre-close net income.
A13: Foregone After-Tax Interest Income ($mm) | B13: 0 | C13: 0 | D13: =-'Sources & Uses'!B25 -> -2002.8484 | E13: =SUM(B13:D13) -> -2002.8484 | F13: =E13 -> -2002.8484 | G13: Cash opportunity cost from Phase 2.
A14: After-Tax PPA Amortization ($mm) | B14: 0 | C14: 0 | D14: =-'Accretion Dilution'!B16 -> -2488.6728 | E14: =SUM(B14:D14) -> -2488.6728 | F14: =E14 -> -2488.6728 | G14: PPA amortization tax-effected at Microsoft FY2023 effective tax rate.
A15: After-Tax Synergies ($mm) | B15: 0 | C15: 0 | D15: 0 | E15: 0 | F15: =F8*(1-'Sources & Uses'!B17) -> 2946.4812 | G15: Pre-tax synergy × (1 − tax rate).
A16: Pro Forma Net Income ($mm) | B16: =B12 -> 72361 | C16: =C12 -> 1513 | D16: =D13+D14+D15 -> -4491.5212 | E16: =SUM(B16:D16) -> 69382.479 | F16: =B12+C12+D13+D14+F15 -> 72328.96 | G16: Matches Phase 3 / Phase 4 earnings logic.
A17: Diluted Shares (mm) | B17: ='Microsoft Standalone'!B9 -> 7472 | C17: 0 | D17: 0 | E17: =B17 -> 7472 | F17: =B17 -> 7472 | G17: All-cash transaction; no new consideration shares issued.
A18: Pro Forma Diluted EPS ($) | B18: ='Microsoft Standalone'!B8 -> 9.68 | E18: =E16/E17 -> 9.2856637 | F18: =F16/F17 -> 9.68 | G18: Pro forma net income / Microsoft diluted shares.
A19: EPS Accretion / (Dilution) | E19: =E18/'Microsoft Standalone'!B8-1 -> -0.040737226 | F19: =F18/'Microsoft Standalone'!B8-1 -> 0 | G19: Compared with Microsoft FY2023 standalone EPS.
A22: Phase 5 Checkpoint Interpretation
A23: Base case | B23: ='Accretion Dilution'!B22 -> -0.040737226 | G23: No synergies: should reproduce the Phase 3 dilution result.
A24: Breakeven case | B24: =F19 -> 0 | G24: Uses the Phase 4 synergy requirement and should produce ~0.0% EPS accretion/dilution.
A25: Next build step | G25: Expand this starter into a fuller combined income statement with revenue/cost structure and a forecast period before Phase 6 balance sheet integration.
A27: 5-Year Combined Pro Forma Forecast (Breakeven Synergies Case) — Rebuilt
A28: Rebuilt to fix two issues found in independent review: (1) the operating margin assumption now uses a genuinely pre-PPA blended margin, so amortization is subtracted exactly once, not twice; (2) foregone interest income is now modeled pre-tax and flows through the standard tax calculation below, rather than double-tax-effecting an already-after-tax figure. Microsoft and Activision now have separate, explicitly labeled growth assumptions.
A30: Forecast Assumptions
A31: Assumption | B31: Value | C31: Note
A32: Microsoft standalone revenue growth (annual) | B32: 0.1 | C32: Model assumption — broadly consistent with recent cloud/AI-driven growth trend, not disclosed guidance
A33: Activision standalone revenue growth (annual) | B33: 0.08 | C33: Model assumption, deliberately more conservative than Microsoft — Activision FY2022 revenue actually declined 14.5% YoY; assumes post-acquisition stabilization, not a return to high growth
A34: Pre-PPA blended operating margin | B34: =('Microsoft Standalone'!B6+'Activision Standalone'!B9)/('Microsoft Standalone'!B5+'Activision Standalone'!B5) -> 0.41100878 | C34: (MSFT standalone OpInc + ATVI standalone OpInc) / (MSFT standalone Rev + ATVI standalone Rev). Held flat across the forecast - genuinely pre-PPA, unlike the prior version.
A35: Tax rate (flat) | B35: ='Sources & Uses'!B17 -> 0.18978625 | C35: Microsoft FY2023A effective rate, reused for consistency
A37: Metric | B37: Year 1 | C37: Year 2 | D37: Year 3 | E37: Year 4 | F37: Year 5
A38: Microsoft Revenue ($mm) | B38: ='Microsoft Standalone'!B5 -> 211915 | C38: =B38*(1+$B$32) -> 233106.5 | D38: =C38*(1+$B$32) -> 256417.15 | E38: =D38*(1+$B$32) -> 282058.86 | F38: =E38*(1+$B$32) -> 310264.75
A39: Activision Revenue ($mm) | B39: ='Activision Standalone'!B5 -> 7528 | C39: =B39*(1+$B$33) -> 8130.24 | D39: =C39*(1+$B$33) -> 8780.6592 | E39: =D39*(1+$B$33) -> 9483.1119 | F39: =E39*(1+$B$33) -> 10241.761
A40: Combined Revenue ($mm) | B40: =B38+B39 -> 219443 | C40: =C38+C39 -> 241236.74 | D40: =D38+D39 -> 265197.81 | E40: =E38+E39 -> 291541.98 | F40: =F38+F39 -> 320506.51
A41: Operating Income before PPA/Synergies ($mm) | B41: =B40*$B$34 -> 90193 | C41: =C40*$B$34 -> 99150.419 | D41: =D40*$B$34 -> 108998.63 | E41: =E40*$B$34 -> 119826.31 | F41: =F40*$B$34 -> 131730.99 | G41: Now genuinely pre-PPA (~41.1%), not the old post-PPA ~39.7% figure
A43: Amortization Schedule (by intangible category)
A44: Marketing-related (24-yr life) | B44: ='Accretion Dilution'!D6 -> 484.125 | C44: ='Accretion Dilution'!D6 -> 484.125 | D44: ='Accretion Dilution'!D6 -> 484.125 | E44: ='Accretion Dilution'!D6 -> 484.125 | F44: ='Accretion Dilution'!D6 -> 484.125
A45: Technology-based (4-yr life, fully amortized after Yr 4) | B45: ='Accretion Dilution'!D7 -> 2422.25 | C45: ='Accretion Dilution'!D7 -> 2422.25 | D45: ='Accretion Dilution'!D7 -> 2422.25 | E45: ='Accretion Dilution'!D7 -> 2422.25 | F45: 0
A46: Customer-related (4-yr life, fully amortized after Yr 4) | B46: ='Accretion Dilution'!D8 -> 165.25 | C46: ='Accretion Dilution'!D8 -> 165.25 | D46: ='Accretion Dilution'!D8 -> 165.25 | E46: ='Accretion Dilution'!D8 -> 165.25 | F46: 0
A47: Total Amortization ($mm, stored negative) | B47: =-(B44+B45+B46) -> -3071.625 | C47: =-(C44+C45+C46) -> -3071.625 | D47: =-(D44+D45+D46) -> -3071.625 | E47: =-(E44+E45+E46) -> -3071.625 | F47: =-(F44+F45+F46) -> -484.125
A49: Synergy Ramp
...

Sheet Pro Forma Balance Sheet
A1: Combined Pro Forma Balance Sheet — Acquisition Date
A2: Microsoft standalone (June 30, 2023) + purchase-accounting adjustments per Microsoft's FINAL Activision purchase price allocation (FY2025 Form 10-K, Note 7 — completed as of September 30, 2024, not the FY2024 preliminary figures).
A4: 1. Microsoft Standalone Balance Sheet (June 30, 2023)
A5: Line Item | B5: Amount ($mm) | C5: Source
A6: Cash & Equivalents | B6: 34704 | C6: stockanalysis.com (Fiscal.ai), sourced from Microsoft FY2023 10-K
A7: Short-Term Investments | B7: 76558 | C7: stockanalysis.com (Fiscal.ai), sourced from Microsoft FY2023 10-K
A8: Accounts Receivable | B8: 48688 | C8: stockanalysis.com (Fiscal.ai), sourced from Microsoft FY2023 10-K
A9: Inventory | B9: 2500 | C9: stockanalysis.com (Fiscal.ai), sourced from Microsoft FY2023 10-K
A10: Other Current Assets | B10: 21807 | C10: stockanalysis.com (Fiscal.ai), sourced from Microsoft FY2023 10-K
A11: Total Current Assets | B11: =SUM(B6:B10) -> 184257 | C11: stockanalysis.com (Fiscal.ai), sourced from Microsoft FY2023 10-K
A12: Net PP&E | B12: 109987 | C12: stockanalysis.com (Fiscal.ai), sourced from Microsoft FY2023 10-K
A13: Goodwill | B13: 67886 | C13: stockanalysis.com (Fiscal.ai), sourced from Microsoft FY2023 10-K
A14: Other Intangible Assets | B14: 9366 | C14: stockanalysis.com (Fiscal.ai), sourced from Microsoft FY2023 10-K
A15: Long-Term Investments | B15: 9879 | C15: stockanalysis.com (Fiscal.ai), sourced from Microsoft FY2023 10-K
A16: Other Long-Term Assets | B16: 30601 | C16: stockanalysis.com (Fiscal.ai), sourced from Microsoft FY2023 10-K
A17: Total Assets | B17: =B11+SUM(B12:B16) -> 411976
A19: Accounts Payable | B19: 18095
A20: Accrued Expenses | B20: 11009
A21: Short-Term Debt | B21: 5247
A22: Unearned Revenue | B22: 50901
A23: Other Current Liabilities | B23: 18897
A24: Total Current Liabilities | B24: =SUM(B19:B23) -> 104149
A25: Long-Term Debt | B25: 41990
A26: Long-Term Leases | B26: 12728
A27: Other Long-Term Liabilities | B27: 46886
A28: Total Liabilities | B28: =B24+SUM(B25:B27) -> 205753
A30: Total Shareholders' Equity | B30: 206223 | C30: Common stock/APIC + AOCI + Retained Earnings, per Microsoft FY2023 10-K
A31: Check: Assets − Liabilities − Equity | B31: =B17-B28-B30 -> 0
A34: 2. Activision Standalone Balance Sheet (December 31, 2022) — Reference Only
A35: Shown for reference/comparison. The pro forma combination below does NOT add these book-value lines directly — it uses Microsoft's own disclosed fair-value purchase price allocation (Section 3), since that is what Microsoft actually recorded, and it consolidates most of Activision's individual asset/liability lines into single 'Other assets' / 'Other liabilities' fair-value figures.
A37: Line Item | B37: Amount ($mm) | C37: Source
A38: Cash & Cash Equivalents | B38: 7060 | C38: Activision Blizzard Q4/FY2022 earnings release exhibit, consolidated balance sheet
A39: Held-to-Maturity Investments | B39: 4932 | C39: Activision Blizzard Q4/FY2022 earnings release exhibit, consolidated balance sheet
A40: Accounts Receivable, net | B40: 1204 | C40: Activision Blizzard Q4/FY2022 earnings release exhibit, consolidated balance sheet
A41: Other Current Assets | B41: 1273 | C41: Activision Blizzard Q4/FY2022 earnings release exhibit, consolidated balance sheet
A42: Total Current Assets | B42: =SUM(B38:B41) -> 14469 | C42: Activision Blizzard Q4/FY2022 earnings release exhibit, consolidated balance sheet
A43: Software Development (non-current) | B43: 641 | C43: Activision Blizzard Q4/FY2022 earnings release exhibit, consolidated balance sheet
A44: PP&E, net | B44: 193 | C44: Activision Blizzard Q4/FY2022 earnings release exhibit, consolidated balance sheet
A45: Deferred Income Taxes, net | B45: 1201 | C45: Activision Blizzard Q4/FY2022 earnings release exhibit, consolidated balance sheet
A46: Other Assets | B46: 508 | C46: Activision Blizzard Q4/FY2022 earnings release exhibit, consolidated balance sheet
...

Sheet Pro Forma Cash Flow
A1: Combined Pro Forma Cash Flow Statement (FY2027E–FY2031E)
A2: Linked to the Phase 5 income statement (Combined Pro Forma Net Income) and the Phase 6 opening balance sheet (beginning cash position). D&A, stock-based compensation, capex, dividends, and buybacks use Microsoft's actual FY2023 amounts as the sourced base, grown at the combined revenue growth rate used elsewhere in this model — not fabricated figures.
A4: Assumptions
A5: Assumption | B5: Value | C5: Source
A6: Microsoft D&A, FY2023A base ($mm) | B6: 13861 | C6: Microsoft FY2023 10-K cash flow statement ("Depreciation, amortization, and other")
A7: Microsoft stock-based compensation, FY2023A base ($mm) | B7: 9611 | C7: Microsoft FY2023 10-K cash flow statement
A8: Microsoft capex, FY2023A base ($mm) | B8: 28107 | C8: Microsoft FY2023 10-K cash flow statement ("Additions to property and equipment")
A9: Microsoft dividends paid, FY2023A base ($mm) | B9: 19800 | C9: Microsoft FY2023 10-K cash flow statement
A10: Dividend growth rate (annual, assumed) | B10: 0.1 | C10: Model assumption — roughly Microsoft's recent historical per-share dividend growth pace, not disclosed guidance
A11: Microsoft share repurchases, FY2023A base ($mm) | B11: 22245 | C11: Microsoft FY2023 10-K cash flow statement ("Common stock repurchased"); held flat across the forecast, not grown
A12: Microsoft debt repayment, FY2023A base ($mm) | B12: 2750 | C12: Microsoft FY2023 10-K cash flow statement; held flat, consistent with Phase 2's no-major-new-acquisition-debt finding
A13: Working capital drag (% of incremental revenue) | B13: 0.03 | C13: Simplified model assumption. Phase 6 built a single acquisition-date balance sheet snapshot, not a 5-year forecasted one, so year-over-year working capital changes are estimated rather than pulled from a multi-year balance sheet.
A15: Metric | B15: Year 1 | C15: Year 2 | D15: Year 3 | E15: Year 4 | F15: Year 5
A16: Cash Flow from Operations
A17: Pro Forma Net Income | B17: ='Pro Forma Income Statement'!B69 -> 70119.099 | C17: ='Pro Forma Income Statement'!C69 -> 78465.042 | D17: ='Pro Forma Income Statement'!D69 -> 87217.936 | E17: ='Pro Forma Income Statement'!E69 -> 96547.44 | F17: ='Pro Forma Income Statement'!F69 -> 108417.52
A18: + PPA Amortization Add-back (non-cash) | B18: =-'Pro Forma Income Statement'!B47 -> 3071.625 | C18: =-'Pro Forma Income Statement'!C47 -> 3071.625 | D18: =-'Pro Forma Income Statement'!D47 -> 3071.625 | E18: =-'Pro Forma Income Statement'!E47 -> 3071.625 | F18: =-'Pro Forma Income Statement'!F47 -> 484.125 | G18: Row 47 is stored negative; negating it adds back the non-cash expense
A19: + Microsoft D&A (grown with revenue) | B19: =$B$6*('Pro Forma Income Statement'!B40/'Pro Forma Income Statement'!$B$40) -> 13861 | C19: =$B$6*('Pro Forma Income Statement'!C40/'Pro Forma Income Statement'!$B$40) -> 15237.59 | D19: =$B$6*('Pro Forma Income Statement'!D40/'Pro Forma Income Statement'!$B$40) -> 16751.078 | E19: =$B$6*('Pro Forma Income Statement'!E40/'Pro Forma Income Statement'!$B$40) -> 18415.093 | F19: =$B$6*('Pro Forma Income Statement'!F40/'Pro Forma Income Statement'!$B$40) -> 20244.623 | G19: Scales the real FY2023A base by combined revenue growth (row 40 above)
A20: + Stock-Based Compensation (grown with revenue) | B20: =$B$7*('Pro Forma Income Statement'!B40/'Pro Forma Income Statement'!$B$40) -> 9611 | C20: =$B$7*('Pro Forma Income Statement'!C40/'Pro Forma Income Statement'!$B$40) -> 10565.506 | D20: =$B$7*('Pro Forma Income Statement'!D40/'Pro Forma Income Statement'!$B$40) -> 11614.935 | E20: =$B$7*('Pro Forma Income Statement'!E40/'Pro Forma Income Statement'!$B$40) -> 12768.737 | F20: =$B$7*('Pro Forma Income Statement'!F40/'Pro Forma Income Statement'!$B$40) -> 14037.304
A21: − Working Capital Drag | B21: =-$B$13*('Pro Forma Income Statement'!B40-'Pro Forma Income Statement'!$E$5) -> 0 | C21: =-$B$13*('Pro Forma Income Statement'!C40-'Pro Forma Income Statement'!B40) -> -653.8122 | D21: =-$B$13*('Pro Forma Income Statement'!D40-'Pro Forma Income Statement'!C40) -> -718.83208 | E21: =-$B$13*('Pro Forma Income Statement'!E40-'Pro Forma Income Statement'!D40) -> -790.32503 | F21: =-$B$13*('Pro Forma Income Statement'!F40-'Pro Forma Income Statement'!E40) -> -868.93606 | G21: Simplified: 3% of incremental revenue vs. the prior year, consuming cash as the combined business grows
A22: Cash Flow from Operations | B22: =B17+B18+B19+B20+B21 -> 96662.724 | C22: =C17+C18+C19+C20+C21 -> 106685.95 | D22: =D17+D18+D19+D20+D21 -> 117936.74 | E22: =E17+E18+E19+E20+E21 -> 130012.57 | F22: =F17+F18+F19+F20+F21 -> 142314.63
A24: Cash Flow from Investing
A25: − Capital Expenditures (grown with revenue) | B25: =-$B$8*('Pro Forma Income Statement'!B40/'Pro Forma Income Statement'!$B$40) -> -28107 | C25: =-$B$8*('Pro Forma Income Statement'!C40/'Pro Forma Income Statement'!$B$40) -> -30898.416 | D25: =-$B$8*('Pro Forma Income Statement'!D40/'Pro Forma Income Statement'!$B$40) -> -33967.43 | E25: =-$B$8*('Pro Forma Income Statement'!E40/'Pro Forma Income Statement'!$B$40) -> -37341.68 | F25: =-$B$8*('Pro Forma Income Statement'!F40/'Pro Forma Income Statement'!$B$40) -> -41051.556
A26: Cash Flow from Investing | B26: =B25 -> -28107 | C26: =C25 -> -30898.416 | D26: =D25 -> -33967.43 | E26: =E25 -> -37341.68 | F26: =F25 -> -41051.556 | G26: The Activision acquisition itself is already reflected in the Phase 6 opening balance sheet (t=0) — no new acquisition cash flow is modeled here for years 1-5
A28: Cash Flow from Financing
A29: − Dividends Paid (grown at assumed rate) | B29: =-$B$9*(1+$B$10) -> -21780 | C29: =B29*(1+$B$10) -> -23958 | D29: =C29*(1+$B$10) -> -26353.8 | E29: =D29*(1+$B$10) -> -28989.18 | F29: =E29*(1+$B$10) -> -31888.098
A30: − Share Repurchases (held flat) | B30: =-$B$11 -> -22245 | C30: =-$B$11 -> -22245 | D30: =-$B$11 -> -22245 | E30: =-$B$11 -> -22245 | F30: =-$B$11 -> -22245
A31: − Debt Repayment (held flat) | B31: =-$B$12 -> -2750 | C31: =-$B$12 -> -2750 | D31: =-$B$12 -> -2750 | E31: =-$B$12 -> -2750 | F31: =-$B$12 -> -2750
A32: Cash Flow from Financing | B32: =B29+B30+B31 -> -46775 | C32: =C29+C30+C31 -> -48953 | D32: =D29+D30+D31 -> -51348.8 | E32: =E29+E30+E31 -> -53984.18 | F32: =F29+F30+F31 -> -56883.098
A35: Cash Reconciliation
A36: Net Change in Cash | B36: =B22+B26+B32 -> 21780.724 | C36: =C22+C26+C32 -> 26834.535 | D36: =D22+D26+D32 -> 32620.511 | E36: =E22+E26+E32 -> 38686.71 | F36: =F22+F26+F32 -> 44379.978
A37: Beginning Cash | B37: ='Pro Forma Balance Sheet'!B82+'Pro Forma Balance Sheet'!B83 -> 122457 | C37: =B38 -> 144237.72 | D37: =C38 -> 171072.26 | E37: =D38 -> 203692.77 | F37: =E38 -> 242379.48 | G37: Year 1 links directly to the Phase 6 opening pro forma cash + ST investments position
A38: Ending Cash | B38: =B37+B36 -> 144237.72 | C38: =C37+C36 -> 171072.26 | D38: =D37+D36 -> 203692.77 | E38: =E37+E36 -> 242379.48 | F38: =F37+F36 -> 286759.46
A40: Centerpiece: Years to Rebuild Deployed Liquidity
A41: Microsoft deployed $61.8B of liquidity to fund the Activision acquisition. Rather than model a leveraged-buyout-style debt paydown story that this deal never was, the relevant question is how quickly ordinary post-close cash generation replenishes that deployed liquidity, after continuing to fund capex, dividends, and buybacks at real, sourced levels.
A43: Metric | B43: Year 1 | C43: Year 2 | D43: Year 3 | E43: Year 4 | F43: Year 5
A44: Cumulative Net Change in Cash Since Close | B44: =B36 -> 21780.724 | C44: =B44+C36 -> 48615.259 | D44: =C44+D36 -> 81235.77 | E44: =D44+E36 -> 119922.48 | F44: =E44+F36 -> 164302.46
A45: Deployed Liquidity Target ($mm) | B45: ='Sources & Uses'!B15 -> 61800 | C45: Links directly to the $61.8B net cash deployed figure from Phase 2
A46: % of Deployed Liquidity Rebuilt | B46: =B44/$B$45 -> 0.3524389 | C46: =C44/$B$45 -> 0.78665467 | D46: =D44/$B$45 -> 1.3144947 | E46: =E44/$B$45 -> 1.9404932 | F46: =F44/$B$45 -> 2.6586158
A48: Years to Rebuild $61.8B of Deployed Liquidity | B48: =IF(B44>=$B$45, ($B$45-0)/B36, IF(C44>=$B$45, 1+($B$45-B44)/C36, IF(D44>=$B$45, 2+($B$45-C44)/D36, IF(E44>=$B$45, 3+($B$45-D44)/E36, IF(F44>=$B$45, 4+($B$45-E44)/F36, "Beyond Year 5"))))) -> 2.4041856 | C48: Fully formula-driven interpolation — identifies which year crosses the target and interpolates within it
